File: CallibrationData/Export2.csv
Time (sec),Stress (MPa),Position (mm),Strain From Position (%)
0.083333,60.57,0.5582,18.61
0.166666,60.53,0.5582,18.61
0.249999,60.45,0.5582,18.61
0.333332,60.36,0.5582,18.61
0.416665,60.27,0.5582,18.61
0.499998,60.21,0.5582,18.61
0.583331,60.17,0.5582,18.61
0.666664,60.13,0.5582,18.61
0.749997,60.10,0.5582,18.61
0.833330,60.07,0.5582,18.61
0.916663,60.03,0.5582,18.61
0.999996,60.00,0.5582,18.61
1.083329,59.97,0.5582,18.61
1.166662,60.22,0.5595,18.65
1.249995,61.31,0.5616,18.72
1.333328,63.24,0.5638,18.79
1.416661,65.90,0.5662,18.87
1.499994,69.19,0.5684,18.95
1.583327,72.74,0.5705,19.02
1.666660,75.96,0.5726,19.09
1.749993,78.79,0.5747,19.16
1.833326,81.19,0.5767,19.22
1.916659,83.03,0.5789,19.30
1.999992,84.33,0.5810,19.37
2.083325,85.12,0.5831,19.44
2.166658,85.44,0.5852,19.51
2.249991,85.50,0.5872,19.57
2.333324,85.52,0.5892,19.64
2.416657,85.53,0.5914,19.71
2.499990,85.55,0.5934,19.78
2.583323,85.57,0.5955,19.85
2.666656,85.61,0.5976,19.92
2.749989,85.67,0.5996,19.99
2.833322,85.73,0.6016,20.05
2.916655,85.80,0.6038,20.13
2.999988,85.88,0.6059,20.20
3.083321,85.95,0.6080,20.27
3.166654,85.99,0.6100,20.33
3.249987,86.02,0.6120,20.40
3.333320,86.04,0.6140,20.47
3.416653,86.03,0.6161,20.54
3.499986,86.03,0.6183,20.61
3.583319,86.01,0.6204,20.68
3.666652,85.98,0.6225,20.75
3.749985,85.95,0.6244,20.81
3.833318,85.92,0.6265,20.88
3.916651,85.91,0.6286,20.95
3.999984,85.95,0.6307,21.02
4.083317,86.02,0.6328,21.09
4.166650,86.08,0.6349,21.16
4.249983,86.16,0.6369,21.23
4.333316,86.23,0.6389,21.30
4.416649,86.27,0.6410,21.37
4.499982,86.30,0.6431,21.44
4.583315,86.34,0.6452,21.51
4.666648,86.39,0.6473,21.58
4.749981,86.44,0.6493,21.64
4.833314,86.49,0.6513,21.71
4.916647,86.53,0.6534,21.78
4.999980,86.59,0.6555,21.85
5.083313,86.64,0.6575,21.92
5.166646,86.68,0.6597,21.99
5.249979,86.71,0.6618,22.06
5.333312,86.73,0.6638,22.13
5.416645,86.73,0.6658,22.19
5.499978,86.73,0.6679,22.26
5.583311,86.73,0.6700,22.33
5.666644,86.73,0.6721,22.40
5.749977,86.74,0.6742,22.47
5.833310,86.74,0.6761,22.54
5.916643,86.75,0.6782,22.61
5.999976,86.76,0.6803,22.68
6.083309,86.77,0.6823,22.74
6.166642,86.78,0.6845,22.82
6.249975,86.79,0.6865,22.88
6.333308,86.79,0.6886,22.95
6.416641,86.78,0.6906,23.02
6.499974,86.76,0.6927,23.09
6.583307,86.75,0.6948,23.16
6.666640,86.73,0.6968,23.23
6.749973,86.72,0.6990,23.30
6.833306,86.73,0.7010,23.37
6.916639,86.76,0.7030,23.43
6.999972,86.85,0.7051,23.50
7.083305,87.01,0.7073,23.58
7.166638,87.24,0.7093,23.64
7.249971,87.55,0.7114,23.71
7.333304,88.13,0.7135,23.78
7.416637,89.05,0.7154,23.85
7.499970,90.32,0.7176,23.92
7.583303,91.96,0.7196,23.99
7.666636,93.97,-0.01348,-0.4493
7.749969,96.99,-0.007959,-0.2653
7.833302,100.6,-0.005828,-0.1943
7.916635,103.9,-0.005047,-0.1682
7.999968,106.8,-0.004584,-0.1528
8.083301,109.3,-0.004240,-0.1413
8.166634,110.5,-0.003952,-0.1317
8.249967,110.7,-0.003665,-0.1222
8.333300,110.9,-0.003477,-0.1159
8.416633,111.0,-0.003389,-0.1130
8.499966,111.1,-0.003201,-0.1067
8.583299,111.1,-0.003113,-0.1038
8.666632,111.2,-0.003026,-0.1009
8.749965,111.2,-0.002938,-0.09792
8.833298,111.2,-0.002850,-0.09500
8.916631,111.2,-0.002762,-0.09207
8.999964,111.2,-0.002700,-0.09000
9.083297,111.2,-0.002600,-0.08667
9.166630,111.2,-0.002600,-0.08667
9.249963,111.2,-0.002511,-0.08370
9.333296,111.2,-0.002500,-0.08333
9.416629,111.2,-0.002435,-0.08118
9.499962,111.2,-0.002400,-0.08000
9.583295,111.2,-0.002400,-0.08000
9.666628,111.2,-0.002300,-0.07667
9.749961,111.1,-0.002300,-0.07667
9.833294,111.1,-0.002300,-0.07667
9.916627,111.1,-0.002300,-0.07667
9.999960,111.1,-0.002200,-0.07333
10.083293,111.1,-0.002200,-0.07333
10.166626,111.1,-0.002200,-0.07333
10.249959,111.0,-0.002200,-0.07333
10.333292,111.0,-0.002100,-0.07000
10.416625,111.0,-0.002100,-0.07000
10.499958,111.0,-0.002100,-0.07000
10.583291,111.0,-0.002100,-0.07000
10.666624,110.9,-0.002100,-0.07000
10.749957,110.9,-0.002100,-0.07000
10.833290,110.9,-0.002043,-0.06809
10.916623,110.9,-0.002000,-0.06667
10.999956,110.9,-0.002000,-0.06667
11.083289,110.8,-0.002000,-0.06667
11.166622,110.8,-0.002000,-0.06667
11.249955,110.8,-0.002000,-0.06667
11.333288,110.8,-0.002000,-0.06667
11.416621,110.8,-0.001928,-0.06427
11.499954,110.8,-0.001900,-0.06333
11.583287,110.8,-0.001900,-0.06333
11.666620,110.7,-0.001900,-0.06333
11.749953,110.7,-0.001900,-0.06333
11.833286,110.7,-0.001900,-0.06333
11.916619,110.7,-0.001900,-0.06333
11.999952,110.7,-0.001900,-0.06333
12.083285,110.7,-0.001900,-0.06333
12.166618,110.7,-0.001900,-0.06333
12.249951,110.6,-0.001900,-0.06333
12.333284,110.6,-0.001800,-0.06000
12.416617,110.6,-0.001800,-0.06000
12.499950,110.6,-0.001800,-0.06000
12.583283,110.6,-0.001800,-0.06000
12.666616,110.6,-0.001800,-0.06000
12.749949,110.6,-0.001800,-0.06000
12.833282,110.6,-0.001800,-0.06000
12.916615,110.5,-0.001800,-0.06000
12.999948,110.5,-0.001800,-0.06000
13.083281,110.5,-0.001800,-0.06000
13.166614,110.5,-0.001800,-0.06000
13.249947,110.5,-0.001800,-0.06000
13.333280,110.5,-0.001800,-0.06000
13.416613,110.5,-0.001800,-0.06000
13.499946,110.5,-0.001733,-0.05777
13.583279,110.5,-0.001700,-0.05667
13.666612,110.5,-0.001700,-0.05667
13.749945,110.5,-0.001700,-0.05667
13.833278,110.4,-0.001700,-0.05667
13.916611,110.4,-0.001700,-0.05667
13.999944,110.4,-0.001700,-0.05667
14.083277,110.4,-0.001700,-0.05667
14.166610,110.4,-0.001700,-0.05667
14.249943,110.4,-0.001700,-0.05667
14.333276,110.4,-0.001700,-0.05667
14.416609,110.4,-0.001700,-0.05667
14.499942,110.4,-0.001700,-0.05667
14.583275,110.4,-0.001700,-0.05667
14.666608,110.4,-0.001700,-0.05667
14.749941,110.4,-0.001700,-0.05667
14.833274,110.4,-0.001700,-0.05667
14.916607,110.4,-0.001629,-0.05432
14.999940,110.4,-0.001600,-0.05333
15.083273,110.4,-0.001600,-0.05333
15.166606,110.4,-0.001600,-0.05333
15.249939,110.3,-0.001600,-0.05333
15.333272,110.3,-0.001600,-0.05333
15.416605,110.3,-0.001600,-0.05333
15.499938,110.3,-0.001600,-0.05333
15.583271,110.3,-0.001600,-0.05333
15.666604,110.6,-0.0004038,-0.01346
15.749937,111.7,0.001546,0.05154
15.833270,114.0,0.003666,0.1222
15.916603,117.1,0.005723,0.1908
15.999936,120.9,0.007864,0.2621
16.083269,125.3,0.009941,0.3314
16.166602,129.3,0.01211,0.4035
16.249935,133.1,0.01417,0.4722
16.333268,136.8,0.01627,0.5424
16.416601,140.6,0.01827,0.6090
16.499934,144.4,0.02029,0.6762
16.583267,148.3,0.02243,0.7475
16.666600,152.2,0.02449,0.8163
16.749933,156.1,0.02655,0.8851
16.833266,160.0,0.02864,0.9548
16.916599,163.9,0.03068,1.023
16.999932,167.8,0.03275,1.092
17.083265,171.8,0.03485,1.162
17.166598,175.9,0.03694,1.231
17.249931,180.1,0.03904,1.301
17.333264,184.6,0.04110,1.370
17.416597,189.2,0.04308,1.436
17.499930,193.8,0.04519,1.506
17.583263,198.4,0.04727,1.576
17.666596,203.2,0.04936,1.645
17.749929,208.1,0.05142,1.714
17.833262,213.0,0.05349,1.783
17.916595,218.0,0.05555,1.852
17.999928,223.0,0.05762,1.921
18.083261,228.0,0.05968,1.989
18.166594,233.1,0.06176,2.059
18.249927,238.3,0.06386,2.129
18.333260,243.5,0.06591,2.197
18.416593,248.8,0.06799,2.266
18.499926,254.1,0.07000,2.333
18.583259,259.5,0.07207,2.402
18.666592,264.9,0.07423,2.474
18.749925,270.4,0.07629,2.543
18.833258,276.0,0.07835,2.612
18.916591,281.7,0.08041,2.680
18.999924,287.4,0.08239,2.746
19.083257,293.1,0.08447,2.816
19.166590,298.9,0.08661,2.887
19.249923,304.8,0.08868,2.956
19.333256,310.7,0.09074,3.025
19.416589,316.7,0.09281,3.094
19.499922,322.7,0.09477,3.159
19.583255,328.8,0.09684,3.228
19.666588,334.9,0.09904,3.301
19.749921,341.1,0.1011,3.369
19.833254,347.3,0.1032,3.440
19.916587,353.6,0.1053,3.509
19.999920,359.9,0.1073,3.575
20.083253,366.2,0.1093,3.642
20.166586,372.5,0.1114,3.712
20.249919,378.9,0.1135,3.782
20.333252,385.4,0.1156,3.853
20.416585,391.9,0.1177,3.922
20.499918,398.5,0.1196,3.988
20.583251,405.0,0.1217,4.057
20.666584,411.5,0.1238,4.126
20.749917,418.2,0.1259,4.198
20.833250,424.8,0.1280,4.267
20.916583,431.6,0.1301,4.336
20.999916,438.4,0.1321,4.404
21.083249,445.1,0.1342,4.472
21.166582,451.8,0.1362,4.539
21.249915,458.6,0.1383,4.611
21.333248,465.4,0.1404,4.679
21.416581,472.3,0.1424,4.748
21.499914,479.3,0.1445,4.816
21.583247,486.2,0.1465,4.882
21.666580,493.1,0.1485,4.951
21.749913,500.1,0.1507,5.023
21.833246,507.0,0.1528,5.092
21.916579,514.1,0.1548,5.161
21.999912,521.3,0.1569,5.230
22.083245,528.5,0.1590,5.299
22.166578,535.6,0.1609,5.365
22.249911,542.7,0.1631,5.436
22.333244,550.0,0.1652,5.506
22.416577,557.3,0.1673,5.577
22.499910,564.6,0.1693,5.645
22.583243,571.9,0.1713,5.711
22.666576,579.2,0.1734,5.780
22.749909,586.5,0.1755,5.849
22.833242,593.8,0.1775,5.918
22.916575,601.1,0.1797,5.990
22.999908,608.5,0.1818,6.059
23.083241,615.8,0.1837,6.124
23.166574,623.2,0.1858,6.192
23.249907,630.5,0.1879,6.262
23.333240,638.0,0.1900,6.334
23.416573,645.4,0.1921,6.403
23.499906,652.8,0.1941,6.472
23.583239,660.3,0.1962,6.540
23.666572,667.7,0.1982,6.606
23.749905,675.1,0.2002,6.672
23.833238,682.4,0.2023,6.743
23.916571,689.7,0.2044,6.813
23.999904,697.2,0.2065,6.883
24.083237,704.7,0.2086,6.953
24.166570,712.2,0.2106,7.019
24.249903,719.6,0.2126,7.088
24.333236,727.0,0.2148,7.159
24.416569,734.3,0.2169,7.228
24.499902,741.6,0.2189,7.298
24.583235,749.1,0.2211,7.369
24.666568,756.5,0.2230,7.435
24.749901,763.7,0.2251,7.504
24.833234,771.0,0.2273,7.576
24.916567,778.1,0.2293,7.644
24.999900,785.2,0.2314,7.713
25.083233,792.4,0.2335,7.782
25.166566,799.6,0.2355,7.850
25.249899,806.6,0.2375,7.917
25.333232,813.6,0.2396,7.988
25.416565,820.6,0.2417,8.057
25.499898,827.4,0.2438,8.126
25.583231,834.2,0.2459,8.198
25.666564,841.0,0.2480,8.265
25.749897,847.7,0.2500,8.333
25.833230,854.2,0.2520,8.401
25.916563,860.7,0.2541,8.471
25.999896,867.1,0.2563,8.542
26.083229,873.4,0.2583,8.611
26.166562,879.6,0.2604,8.680
26.249895,885.6,0.2624,8.747
26.333228,891.4,0.2645,8.817
26.416561,897.1,0.2666,8.886
26.499894,902.6,0.2687,8.955
26.583227,907.9,0.2707,9.024
26.666560,913.0,0.2728,9.093
26.749893,917.8,0.2748,9.161
26.833226,922.4,0.2769,9.230
26.916559,926.7,0.2790,9.299
26.999892,930.8,0.2811,9.369
27.083225,934.5,0.2831,9.437
27.166558,938.1,0.2852,9.508
27.249891,941.4,0.2873,9.576
27.333224,944.3,0.2893,9.643
27.416557,947.0,0.2914,9.713
27.499890,949.5,0.2935,9.785
27.583223,951.8,0.2956,9.852
27.666556,953.9,0.2976,9.921
27.749889,955.7,0.2997,9.990
27.833222,957.3,0.3017,10.06
27.916555,958.7,0.3038,10.13
27.999888,960.0,0.3059,10.20
28.083221,961.0,0.3080,10.27
28.166554,961.9,0.3101,10.34
28.249887,962.6,0.3121,10.40
28.333220,963.1,0.3141,10.47
28.416553,963.4,0.3163,10.54
28.499886,963.6,0.3183,10.61
28.583219,963.7,0.3205,10.68
28.666552,963.6,0.3225,10.75
28.749885,963.3,0.3245,10.82
28.833218,962.9,0.3266,10.89
28.916551,962.4,0.3286,10.95
28.999884,961.8,0.3307,11.02
29.083217,961.2,0.3328,11.09
29.166550,960.4,0.3349,11.16
29.249883,959.6,0.3369,11.23
29.333216,958.7,0.3389,11.30
29.416549,957.7,0.3410,11.37
29.499882,956.7,0.3431,11.44
29.583215,955.7,0.3452,11.51
29.666548,954.6,0.3473,11.58
29.749881,953.5,0.3494,11.65
29.833214,952.3,0.3513,11.71
29.916547,951.0,0.3535,11.78
29.999880,949.8,0.3556,11.85
30.083213,948.6,0.3577,11.92
30.166546,947.2,0.3597,11.99
30.249879,946.0,0.3618,12.06
30.333212,944.5,0.3638,12.13
30.416545,943.0,0.3659,12.20
30.499878,941.6,0.3680,12.27
30.583211,940.2,0.3701,12.34
30.666544,938.8,0.3721,12.40
30.749877,937.3,0.3742,12.47
30.833210,935.7,0.3762,12.54
30.916543,934.1,0.3782,12.61
30.999876,932.4,0.3803,12.68
31.083209,930.9,0.3824,12.75
31.166542,929.3,0.3845,12.82
31.249875,927.7,0.3865,12.88
31.333208,926.0,0.3886,12.95
31.416541,924.3,0.3906,13.02
31.499874,922.5,0.3927,13.09
31.583207,920.9,0.3948,13.16
31.666540,919.2,0.3970,13.23
31.749873,917.5,0.3990,13.30
31.833206,915.8,0.4010,13.37
31.916539,914.0,0.4031,13.44
31.999872,912.2,0.4051,13.50
32.083205,910.5,0.4073,13.58
32.166538,908.7,0.4094,13.65
32.249871,907.0,0.4115,13.72
32.333204,905.2,0.4136,13.79
32.416537,903.4,0.4155,13.85
32.499870,901.5,0.4176,13.92
32.583203,899.8,0.4197,13.99
32.666536,898.0,0.4219,14.06
32.749869,896.3,0.4239,14.13
32.833202,894.5,0.4260,14.20
32.916535,892.7,0.4279,14.26
32.999868,890.8,0.4300,14.33
33.083201,889.0,0.4321,14.40
33.166534,887.3,0.4342,14.47
33.249867,885.6,0.4363,14.54
33.333200,883.8,0.4384,14.61
33.416533,882.0,0.4404,14.68
33.499866,880.2,0.4425,14.75
33.583199,878.3,0.4445,14.82
33.666532,876.6,0.4466,14.89
33.749865,874.8,0.4487,14.96
33.833198,873.1,0.4508,15.03
33.916531,871.3,0.4529,15.10
33.999864,869.5,0.4549,15.16
34.083197,867.6,0.4569,15.23
34.166530,865.9,0.4591,15.30
34.249863,864.1,0.4612,15.37
34.333196,862.3,0.4633,15.44
34.416529,860.5,0.4653,15.51
34.499862,858.7,0.4673,15.58
34.583195,856.7,0.4693,15.64
34.666528,855.0,0.4715,15.72
34.749861,853.1,0.4736,15.79
34.833194,851.3,0.4756,15.85
34.916527,849.6,0.4777,15.92
34.999860,847.7,0.4797,15.99
35.083193,845.8,0.4817,16.06
35.166526,844.0,0.4838,16.13
35.249859,842.2,0.4859,16.20
35.333192,840.4,0.4880,16.27
35.416525,838.7,0.4902,16.34
35.499858,836.8,0.4921,16.40
35.583191,834.9,0.4942,16.47
35.666524,833.1,0.4963,16.54
35.749857,831.2,0.4983,16.61
35.833190,829.4,0.5004,16.68
35.916523,827.6,0.5026,16.75
35.999856,825.8,0.5045,16.82
36.083189,823.8,0.5066,16.89
36.166522,821.9,0.5087,16.96
36.249855,820.1,0.5108,17.03
36.333188,818.2,0.5128,17.09
36.416521,816.3,0.5150,17.17
36.499854,814.4,0.5170,17.23
36.583187,812.5,0.5190,17.30
36.666520,810.5,0.5211,17.37
36.749853,808.7,0.5232,17.44
36.833186,806.8,0.5253,17.51
36.916519,804.9,0.5274,17.58
36.999852,803.0,0.5294,17.65
37.083185,801.1,0.5314,17.71
37.166518,799.1,0.5335,17.78
37.249851,797.2,0.5356,17.85
37.333184,795.2,0.5377,17.92
37.416517,793.3,0.5398,17.99
37.499850,791.4,0.5418,18.06
37.583183,789.4,0.5439,18.13
37.666516,787.4,0.5459,18.20
37.749849,785.4,0.5481,18.27
37.833182,783.4,0.5501,18.34
37.916515,781.4,0.5522,18.41
37.999848,779.4,0.5543,18.48
38.083181,777.4,0.5563,18.54
38.166514,775.3,0.5583,18.61
38.249847,773.3,0.5604,18.68
38.333180,771.3,0.5625,18.75
38.416513,769.2,0.5646,18.82
38.499846,767.2,0.5666,18.89
38.583179,765.1,0.5687,18.96
38.666512,763.0,0.5708,19.03
38.749845,760.9,0.5728,19.09
38.833178,758.8,0.5749,19.16
38.916511,756.8,0.5770,19.23
38.999844,754.6,0.5791,19.30
39.083177,752.5,0.5811,19.37
39.166510,750.3,0.5831,19.44
39.249843,748.2,0.5852,19.51
39.333176,746.0,0.5874,19.58
39.416509,743.9,0.5894,19.65
39.499842,741.7,0.5915,19.72
39.583175,739.5,0.5935,19.78
39.666508,737.2,0.5956,19.85
39.749841,735.0,0.5976,19.92
39.833174,732.8,0.5998,19.99
39.916507,730.6,0.6018,20.06
39.999840,728.3,0.6039,20.13
40.083173,726.1,0.6059,20.20
40.166506,723.8,0.6080,20.27
40.249839,721.4,0.6100,20.33
40.333172,719.1,0.6122,20.41
40.416505,716.8,0.6142,20.47
40.499838,714.4,0.6163,20.54
40.583171,712.1,0.6184,20.61
40.666504,709.7,0.6204,20.68
40.749837,707.2,0.6225,20.75
40.833170,704.8,0.6247,20.82
40.916503,702.4,0.6267,20.89
40.999836,699.9,0.6288,20.96
41.083169,697.5,0.6308,21.03
41.166502,695.0,0.6328,21.09
41.249835,692.4,0.6348,21.16
41.333168,689.9,0.6370,21.23
41.416501,687.5,0.6391,21.30
41.499834,684.9,0.6412,21.37
41.583167,682.4,0.6432,21.44
41.666500,679.8,0.6453,21.51
41.749833,677.1,0.6473,21.58
41.833166,674.4,0.6494,21.65
41.916499,671.9,0.6515,21.72
41.999832,669.2,0.6536,21.79
42.083165,666.5,0.6557,21.86
42.166498,663.8,0.6577,21.92
42.249831,661.0,0.6597,21.99
42.333164,658.1,0.6618,22.06
42.416497,655.4,0.6639,22.13
42.499830,652.6,0.6660,22.20
42.583163,649.7,0.6681,22.27
42.666496,646.8,0.6701,22.34
42.749829,643.8,0.6721,22.40
42.833162,640.8,0.6742,22.47
42.916495,637.8,0.6763,22.54
42.999828,634.8,0.6784,22.61
43.083161,631.7,0.6805,22.68
43.166494,628.6,0.6825,22.75
43.249827,625.4,0.6846,22.82
43.333160,622.1,0.6866,22.89
43.416493,618.8,0.6888,22.96
43.499826,615.5,0.6908,23.03
43.583159,612.1,0.6929,23.10
43.666492,608.6,0.6950,23.17
43.749825,604.9,0.6970,23.23
43.833158,601.1,0.6990,23.30
43.916491,597.2,0.7011,23.37
43.999824,593.1,0.7032,23.44
44.083157,588.7,0.7053,23.51
44.166490,582.4,0.7074,23.58
44.249823,562.2,0.7096,23.65
44.333156,464.2,0.7118,23.73
44.416489,347.2,0.7137,23.79
44.499822,230.3,0.7157,23.86
Time (sec),Stress (MPa),Position (mm),Strain From Position (%)
0.083333,50.26,0.5180,17.27
0.166666,50.25,0.5180,17.27
0.249999,50.22,0.5180,17.27
0.333332,50.29,0.5187,17.29
0.416665,51.20,0.5208,17.36
0.499998,53.25,0.5231,17.44
0.583331,56.21,0.5253,17.51
0.666664,59.85,0.5275,17.58
0.749997,63.94,0.5296,17.65
0.833330,67.85,0.5317,17.72
0.916663,71.24,0.5339,17.80
0.999996,74.29,0.5360,17.87
1.083329,77.12,0.5381,17.94
1.166662,79.48,0.5402,18.01
1.249995,81.27,0.5422,18.07
1.333328,82.41,0.5442,18.14
1.416661,83.03,0.5464,18.21
1.499994,83.26,0.5485,18.28
1.583327,83.31,0.5505,18.35
1.666660,83.34,0.5526,18.42
1.749993,83.35,0.5546,18.49
1.833326,83.37,0.5567,18.56
1.916659,83.36,0.5588,18.63
1.999992,83.37,0.5609,18.70
2.083325,83.38,0.5630,18.77
2.166658,83.37,0.5650,18.83
2.249991,83.38,0.5671,18.90
2.333324,83.41,0.5691,18.97
2.416657,83.41,0.5712,19.04
2.499990,83.40,0.5733,19.11
2.583323,83.42,0.5754,19.18
2.666656,83.42,0.5775,19.25
2.749989,83.46,0.5795,19.32
2.833322,83.53,0.5816,19.39
2.916655,83.60,0.5836,19.45
2.999988,83.69,0.5858,19.53
3.083321,83.78,0.5878,19.59
3.166654,83.85,0.5899,19.66
3.249987,83.91,0.5920,19.73
3.333320,83.96,0.5940,19.80
3.416653,84.00,0.5960,19.87
3.499986,84.03,0.5981,19.94
3.583319,84.06,0.6003,20.01
3.666652,84.08,0.6024,20.08
3.749985,84.10,0.6044,20.15
3.833318,84.13,0.6064,20.21
3.916651,84.16,0.6084,20.28
3.999984,84.19,0.6106,20.35
4.083317,84.23,0.6127,20.42
4.166650,84.27,0.6147,20.49
4.249983,84.31,0.6168,20.56
4.333316,84.34,0.6188,20.63
4.416649,84.36,0.6209,20.70
4.499982,84.38,0.6230,20.77
4.583315,84.38,0.6250,20.83
4.666648,84.39,0.6272,20.91
4.749981,84.39,0.6293,20.98
4.833314,84.38,0.6313,21.04
4.916647,84.38,0.6333,21.11
4.999980,84.38,0.6353,21.18
5.083313,84.38,0.6375,21.25
5.166646,84.38,0.6396,21.32
5.249979,84.38,0.6417,21.39
5.333312,84.39,0.6437,21.46
5.416645,84.40,0.6457,21.52
5.499978,84.42,0.6478,21.59
5.583311,84.43,0.6499,21.66
5.666644,84.44,0.6520,21.73
5.749977,84.45,0.6541,21.80
5.833310,84.46,0.6561,21.87
5.916643,84.49,0.6581,21.94
5.999976,84.53,0.6602,22.01
6.083309,84.60,0.6623,22.08
6.166642,84.69,0.6644,22.15
6.249975,84.79,0.6665,22.22
6.333308,84.91,0.6685,22.28
6.416641,85.05,0.6706,22.35
6.499974,85.22,0.6726,22.42
6.583307,85.54,0.6748,22.49
6.666640,86.05,0.6767,22.56
6.749973,86.82,0.6789,22.63
6.833306,88.02,0.6810,22.70
6.916639,89.59,0.6830,22.77
6.999972,91.52,0.6850,22.83
7.083305,93.83,-0.009186,-0.3062
7.166638,97.03,-0.005194,-0.1731
7.249971,100.7,-0.003499,-0.1166
7.333304,104.2,-0.002894,-0.09646
7.416637,107.1,-0.002563,-0.08542
7.499970,109.4,-0.002331,-0.07771
7.583303,110.6,-0.002100,-0.07000
7.666636,110.8,-0.002000,-0.06667
7.749969,110.9,-0.001900,-0.06333
7.833302,111.0,-0.001800,-0.06000
7.916635,111.0,-0.001700,-0.05667
7.999968,111.0,-0.001600,-0.05333
8.083301,111.0,-0.001511,-0.05038
8.166634,111.0,-0.001500,-0.05000
8.249967,111.0,-0.001400,-0.04667
8.333300,111.0,-0.001400,-0.04667
8.416633,111.0,-0.001300,-0.04333
8.499966,110.9,-0.001300,-0.04333
8.583299,110.9,-0.001300,-0.04333
8.666632,110.9,-0.001200,-0.04000
8.749965,110.9,-0.001200,-0.04000
8.833298,110.8,-0.001200,-0.04000
8.916631,110.8,-0.001100,-0.03667
8.999964,110.8,-0.001100,-0.03667
9.083297,110.8,-0.001100,-0.03667
9.166630,110.8,-0.001100,-0.03667
9.249963,110.7,-0.001000,-0.03333
9.333296,110.7,-0.001000,-0.03333
9.416629,110.7,-0.001000,-0.03333
9.499962,110.9,0.0002568,0.008561
9.583295,112.2,0.002248,0.07495
9.666628,114.5,0.004415,0.1472
9.749961,117.6,0.006498,0.2166
9.833294,121.6,0.008574,0.2858
9.916627,126.2,0.01066,0.3555
9.999960,130.5,0.01272,0.4241
10.083293,134.6,0.01480,0.4933
10.166626,138.8,0.01687,0.5625
10.249959,143.0,0.01895,0.6316
10.333292,147.3,0.02102,0.7008
10.416625,151.6,0.02312,0.7708
10.499958,156.0,0.02517,0.8391
10.583291,160.5,0.02724,0.9080
10.666624,165.0,0.02932,0.9775
10.749957,169.6,0.03140,1.047
10.833290,174.0,0.03348,1.116
10.916623,178.4,0.03555,1.185
10.999956,182.9,0.03762,1.254
11.083289,187.5,0.03970,1.323
11.166622,192.2,0.04178,1.393
11.249955,197.2,0.04385,1.462
11.333288,202.3,0.04593,1.531
11.416621,207.6,0.04800,1.600
11.499954,213.0,0.05008,1.669
11.583287,218.4,0.05215,1.738
11.666620,223.8,0.05423,1.808
11.749953,229.3,0.05630,1.877
11.833286,234.8,0.05840,1.947
11.916619,240.4,0.06045,2.015
11.999952,246.0,0.06248,2.083
12.083285,251.7,0.06450,2.150
12.166618,257.4,0.06658,2.219
12.249951,263.1,0.06875,2.292
12.333284,268.8,0.07079,2.360
12.416617,274.6,0.07281,2.427
12.499950,280.6,0.07488,2.496
12.583283,286.4,0.07695,2.565
12.666616,292.3,0.07903,2.634
12.749949,298.3,0.08110,2.703
12.833282,304.3,0.08319,2.773
12.916615,310.4,0.08526,2.842
12.999948,316.6,0.08733,2.911
13.083281,322.7,0.08931,2.977
13.166614,328.8,0.09138,3.046
13.249947,335.0,0.09355,3.118
13.333280,341.3,0.09563,3.188
13.416613,347.6,0.09770,3.257
13.499946,354.1,0.09978,3.326
13.583279,360.6,0.1018,3.392
13.666612,367.0,0.1038,3.460
13.749945,373.4,0.1060,3.533
13.833278,380.1,0.1081,3.603
13.916611,386.7,0.1102,3.672
13.999944,393.4,0.1122,3.741
14.083277,400.2,0.1142,3.807
14.166610,406.9,0.1163,3.876
14.249943,413.7,0.1184,3.947
14.333276,420.5,0.1205,4.018
14.416609,427.4,0.1225,4.085
14.499942,434.3,0.1246,4.154
14.583275,441.4,0.1267,4.222
14.666608,448.4,0.1287,4.289
14.749941,455.3,0.1308,4.358
14.833274,462.3,0.1329,4.429
14.916607,469.4,0.1350,4.499
14.999940,476.6,0.1370,4.568
15.083273,483.8,0.1391,4.637
15.166606,491.0,0.1411,4.703
15.249939,498.1,0.1431,4.771
15.333272,505.3,0.1453,4.844
15.416605,512.6,0.1474,4.914
15.499938,519.9,0.1494,4.980
15.583271,527.3,0.1516,5.052
15.666604,534.7,0.1535,5.118
15.749937,542.0,0.1555,5.184
15.833270,549.4,0.1577,5.256
15.916603,556.9,0.1598,5.326
15.999936,564.5,0.1619,5.397
16.083269,572.1,0.1640,5.466
16.166602,579.7,0.1660,5.533
16.249935,587.2,0.1680,5.599
16.333268,594.7,0.1701,5.671
16.416601,602.3,0.1722,5.740
16.499934,609.9,0.1743,5.810
16.583267,617.5,0.1764,5.879
16.666600,625.2,0.1783,5.944
16.749933,632.8,0.1804,6.014
16.833266,640.3,0.1825,6.083
16.916599,647.9,0.1846,6.152
16.999932,655.4,0.1867,6.224
17.083265,663.2,0.1888,6.294
17.166598,671.1,0.1908,6.359
17.249931,678.8,0.1928,6.428
17.333264,686.5,0.1948,6.494
17.416597,694.3,0.1970,6.567
17.499930,702.1,0.1991,6.636
17.583263,710.0,0.2012,6.705
17.666596,717.9,0.2032,6.774
17.749929,725.8,0.2053,6.842
17.833262,733.6,0.2073,6.910
17.916595,741.4,0.2095,6.982
17.999928,749.2,0.2115,7.050
18.083261,757.0,0.2136,7.120
18.166594,764.9,0.2157,7.190
18.249927,772.8,0.2177,7.255
18.333260,780.5,0.2197,7.324
18.416593,788.3,0.2218,7.394
18.499926,796.0,0.2239,7.464
18.583259,803.8,0.2261,7.535
18.666592,811.6,0.2281,7.605
18.749925,819.5,0.2301,7.670
18.833258,827.2,0.2321,7.738
18.916591,834.8,0.2343,7.809
18.999924,842.4,0.2363,7.876
19.083257,850.0,0.2384,7.947
19.166590,857.6,0.2404,8.014
19.249923,865.0,0.2424,8.080
19.333256,872.4,0.2445,8.151
19.416589,879.6,0.2467,8.222
19.499922,886.8,0.2487,8.290
19.583255,893.9,0.2509,8.362
19.666588,900.8,0.2529,8.431
19.749921,907.7,0.2550,8.500
19.833254,914.3,0.2571,8.569
19.916587,920.5,0.2591,8.637
19.999920,926.6,0.2612,8.707
20.083253,932.4,0.2633,8.777
20.166586,937.9,0.2654,8.846
20.249919,943.3,0.2675,8.915
20.333252,948.2,0.2695,8.984
20.416585,952.7,0.2715,9.051
20.499918,957.0,0.2737,9.122
20.583251,960.8,0.2757,9.192
20.666584,964.2,0.2778,9.261
20.749917,967.4,0.2799,9.330
20.833250,970.0,0.2819,9.397
20.916583,972.3,0.2839,9.465
20.999916,974.2,0.2861,9.536
21.083249,975.8,0.2881,9.605
21.166582,977.1,0.2902,9.674
21.249915,978.2,0.2924,9.746
21.333248,978.9,0.2943,9.811
21.416581,979.4,0.2963,9.878
21.499914,979.7,0.2985,9.950
21.583247,979.8,0.3006,10.02
21.666580,979.7,0.3027,10.09
21.749913,979.6,0.3048,10.16
21.833246,979.3,0.3068,10.23
21.916579,978.8,0.3088,10.29
21.999912,978.3,0.3110,10.37
22.083245,977.8,0.3130,10.43
22.166578,977.1,0.3151,10.50
22.249911,976.4,0.3172,10.57
22.333244,975.7,0.3192,10.64
22.416577,974.8,0.3213,10.71
22.499910,973.9,0.3234,10.78
22.583243,973.1,0.3254,10.85
22.666576,972.2,0.3276,10.92
22.749909,971.2,0.3296,10.99
22.833242,970.2,0.3316,11.05
22.916575,969.1,0.3337,11.12
22.999908,968.0,0.3358,11.19
23.083241,966.9,0.3379,11.26
23.166574,965.8,0.3400,11.33
23.249907,964.6,0.3420,11.40
23.333240,963.4,0.3441,11.47
23.416573,962.1,0.3461,11.54
23.499906,960.7,0.3482,11.61
23.583239,959.4,0.3503,11.68
23.666572,958.0,0.3524,11.75
23.749905,956.7,0.3545,11.82
23.833238,955.3,0.3566,11.89
23.916571,953.8,0.3586,11.95
23.999904,952.2,0.3606,12.02
24.083237,950.7,0.3627,12.09
24.166570,949.2,0.3648,12.16
24.249903,947.7,0.3668,12.23
24.333236,946.1,0.3689,12.30
24.416569,944.5,0.3709,12.36
24.499902,942.8,0.3729,12.43
24.583235,941.2,0.3752,12.51
24.666568,939.6,0.3772,12.57
24.749901,937.8,0.3793,12.64
24.833234,936.2,0.3814,12.71
24.916567,934.4,0.3833,12.78
24.999900,932.6,0.3854,12.85
25.083233,930.9,0.3876,12.92
25.166566,929.2,0.3896,12.99
25.249899,927.4,0.3917,13.06
25.333232,925.7,0.3938,13.13
25.416565,923.9,0.3958,13.19
25.499898,922.0,0.3979,13.26
25.583231,920.2,0.3999,13.33
25.666564,918.5,0.4021,13.40
25.749897,916.7,0.4042,13.47
25.833230,915.0,0.4063,13.54
25.916563,913.2,0.4083,13.61
25.999896,911.3,0.4103,13.68
26.083229,909.4,0.4123,13.74
26.166562,907.6,0.4145,13.82
26.249895,905.9,0.4166,13.89
26.333228,904.1,0.4187,13.96
26.416561,902.3,0.4207,14.02
26.499894,900.4,0.4227,14.09
26.583227,898.5,0.4246,14.15
26.666560,896.7,0.4268,14.23
26.749893,895.0,0.4289,14.30
26.833226,893.2,0.4310,14.37
26.916559,891.5,0.4331,14.44
26.999892,889.6,0.4351,14.50
27.083225,887.8,0.4371,14.57
27.166558,885.9,0.4393,14.64
27.249891,884.2,0.4414,14.71
27.333224,882.4,0.4435,14.78
27.416557,880.6,0.4456,14.85
27.499890,878.8,0.4475,14.92
27.583223,876.9,0.4496,14.99
27.666556,874.9,0.4517,15.06
27.749889,873.2,0.4538,15.13
27.833222,871.4,0.4559,15.20
27.916555,869.6,0.4580,15.27
27.999888,867.7,0.4599,15.33
28.083221,865.8,0.4620,15.40
28.166554,863.9,0.4641,15.47
28.249887,862.1,0.4662,15.54
28.333220,860.3,0.4683,15.61
28.416553,858.5,0.4704,15.68
28.499886,856.7,0.4724,15.75
28.583219,854.8,0.4744,15.81
28.666552,852.9,0.4765,15.88
28.749885,851.1,0.4786,15.95
28.833218,849.3,0.4807,16.02
28.916551,847.5,0.4828,16.09
28.999884,845.7,0.4848,16.16
29.083217,843.8,0.4868,16.23
29.166550,841.9,0.4889,16.30
29.249883,840.1,0.4910,16.37
29.333216,838.2,0.4931,16.44
29.416549,836.4,0.4952,16.51
29.499882,834.5,0.4973,16.58
29.583215,832.7,0.4993,16.64
29.666548,830.7,0.5013,16.71
29.749881,828.8,0.5035,16.78
29.833214,826.9,0.5055,16.85
29.916547,825.0,0.5077,16.92
29.999880,823.2,0.5098,16.99
30.083213,821.2,0.5118,17.06
30.166546,819.2,0.5138,17.13
30.249879,817.3,0.5159,17.20
30.333212,815.4,0.5180,17.27
30.416545,813.4,0.5201,17.34
30.499878,811.5,0.5222,17.41
30.583211,809.6,0.5242,17.47
30.666544,807.6,0.5262,17.54
30.749877,805.6,0.5283,17.61
30.833210,803.7,0.5304,17.68
30.916543,801.7,0.5325,17.75
30.999876,799.7,0.5346,17.82
31.083209,797.7,0.5366,17.89
31.166542,795.7,0.5386,17.95
31.249875,793.6,0.5407,18.02
31.333208,791.6,0.5428,18.09
31.416541,789.6,0.5448,18.16
31.499874,787.6,0.5470,18.23
31.583207,785.6,0.5490,18.30
31.666540,783.5,0.5511,18.37
31.749873,781.4,0.5532,18.44
31.833206,779.3,0.5552,18.51
31.916539,777.2,0.5573,18.58
31.999872,775.1,0.5594,18.65
32.083205,773.0,0.5614,18.71
32.166538,770.9,0.5635,18.78
32.249871,768.7,0.5656,18.85
32.333204,766.6,0.5676,18.92
32.416537,764.4,0.5697,18.99
32.499870,762.3,0.5717,19.06
32.583203,760.1,0.5739,19.13
32.666536,757.9,0.5759,19.20
32.749869,755.6,0.5779,19.26
32.833202,753.4,0.5800,19.33
32.916535,751.1,0.5821,19.40
32.999868,748.8,0.5842,19.47
33.083201,746.5,0.5862,19.54
33.166534,744.2,0.5883,19.61
33.249867,741.9,0.5903,19.68
33.333200,739.5,0.5924,19.75
33.416533,737.1,0.5946,19.82
33.499866,734.7,0.5966,19.89
33.583199,732.3,0.5987,19.96
33.666532,729.8,0.6007,20.02
33.749865,727.3,0.6027,20.09
33.833198,724.8,0.6048,20.16
33.916531,722.3,0.6069,20.23
33.999864,719.7,0.6090,20.30
34.083197,717.1,0.6111,20.37
34.166530,714.4,0.6131,20.44
34.249863,711.7,0.6152,20.51
34.333196,708.9,0.6173,20.58
34.416529,706.1,0.6193,20.64
34.499862,703.2,0.6214,20.71
34.583195,700.2,0.6235,20.78
34.666528,697.2,0.6255,20.85
34.749861,694.2,0.6276,20.92
34.833194,691.0,0.6296,20.99
34.916527,687.9,0.6317,21.06
34.999860,684.6,0.6338,21.13
35.083193,681.2,0.6359,21.20
35.166526,677.6,0.6380,21.27
35.249859,673.8,0.6400,21.33
35.333192,669.7,0.6420,21.40
35.416525,665.5,0.6441,21.47
35.499858,660.0,0.6463,21.54
35.583191,652.4,0.6483,21.61
35.666524,642.6,0.6504,21.68
35.749857,628.3,0.6524,21.75
35.833190,609.5,0.6544,21.81
35.916523,585.8,0.6566,21.89
35.999856,489.2,0.6590,21.97
36.083189,365.3,0.6609,22.03
36.166522,246.4,0.6629,22.10