File: CallibrationData/TiniusOlsen/174PH_2.csv
Time (sec),Stress (MPa),Position (mm),Strain From Position (%)
0.083333,60.91,0.4889,16.30
0.166666,60.90,0.4889,16.30
0.249999,60.88,0.4889,16.30
0.333332,60.94,0.4895,16.32
0.416665,61.76,0.4915,16.38
0.499998,63.59,0.4937,16.46
0.583331,66.35,0.4960,16.53
0.666664,69.84,0.4982,16.61
0.749997,73.81,0.5003,16.68
0.833330,77.49,0.5025,16.75
0.916663,80.33,0.5045,16.82
0.999996,82.31,0.5067,16.89
1.083329,83.58,0.5088,16.96
1.166662,84.25,0.5109,17.03
1.249995,84.44,0.5130,17.10
1.333328,84.42,0.5150,17.17
1.416661,84.37,0.5171,17.24
1.499994,84.32,0.5192,17.31
1.583327,84.28,0.5213,17.38
1.666660,84.24,0.5233,17.44
1.749993,84.20,0.5255,17.52
1.833326,84.18,0.5275,17.58
1.916659,84.16,0.5295,17.65
1.999992,84.14,0.5315,17.72
2.083325,84.14,0.5337,17.79
2.166658,84.14,0.5358,17.86
2.249991,84.14,0.5378,17.93
2.333324,84.13,0.5398,17.99
2.416657,84.13,0.5419,18.06
2.499990,84.12,0.5439,18.13
2.583323,84.12,0.5461,18.20
2.666656,84.12,0.5481,18.27
2.749989,84.15,0.5502,18.34
2.833322,84.22,0.5522,18.41
2.916655,84.31,0.5543,18.48
2.999988,84.39,0.5564,18.55
3.083321,84.48,0.5585,18.62
3.166654,84.54,0.5606,18.69
3.249987,84.57,0.5626,18.75
3.333320,84.59,0.5647,18.82
3.416653,84.63,0.5667,18.89
3.499986,84.67,0.5688,18.96
3.583319,84.71,0.5709,19.03
3.666652,84.76,0.5730,19.10
3.749985,84.80,0.5751,19.17
3.833318,84.85,0.5772,19.24
3.916651,84.89,0.5792,19.31
3.999984,84.93,0.5812,19.37
4.083317,84.97,0.5833,19.44
4.166650,85.00,0.5854,19.51
4.249983,85.03,0.5874,19.58
4.333316,85.06,0.5896,19.65
4.416649,85.09,0.5916,19.72
4.499982,85.13,0.5936,19.79
4.583315,85.16,0.5956,19.85
4.666648,85.20,0.5979,19.93
4.749981,85.23,0.5999,20.00
4.833314,85.26,0.6020,20.07
4.916647,85.29,0.6040,20.13
4.999980,85.30,0.6060,20.20
5.083313,85.30,0.6081,20.27
5.166646,85.31,0.6102,20.34
5.249979,85.29,0.6124,20.41
5.333312,85.27,0.6144,20.48
5.416645,85.26,0.6165,20.55
5.499978,85.24,0.6185,20.62
5.583311,85.22,0.6205,20.68
5.666644,85.20,0.6226,20.75
5.749977,85.19,0.6248,20.83
5.833310,85.18,0.6268,20.89
5.916643,85.19,0.6289,20.96
5.999976,85.23,0.6309,21.03
6.083309,85.34,0.6329,21.10
6.166642,85.55,0.6350,21.17
6.249975,85.85,0.6372,21.24
6.333308,86.23,0.6392,21.31
6.416641,86.72,0.6414,21.38
6.499974,87.51,0.6433,21.44
6.583307,88.64,0.6454,21.51
6.666640,90.23,0.6475,21.58
6.749973,92.45,-0.008928,-0.2976
6.833306,95.39,-0.005500,-0.1833
6.916639,99.28,-0.003016,-0.1005
6.999972,103.1,-0.002533,-0.08443
7.083305,106.3,-0.002192,-0.07307
7.166638,108.9,-0.001956,-0.06519
7.249971,110.5,-0.001850,-0.06167
7.333304,110.9,-0.001700,-0.05667
7.416637,111.0,-0.001539,-0.05131
7.499970,111.0,-0.001500,-0.05000
7.583303,111.1,-0.001400,-0.04667
7.666636,111.1,-0.001300,-0.04333
7.749969,111.1,-0.001300,-0.04333
7.833302,111.1,-0.001200,-0.04000
7.916635,111.1,-0.001106,-0.03688
7.999968,111.1,-0.001100,-0.03667
8.083301,111.1,-0.001100,-0.03667
8.166634,111.1,-0.001000,-0.03333
8.249967,111.1,-0.001000,-0.03333
8.333300,111.1,-0.001000,-0.03333
8.416633,111.1,-0.0009000,-0.03000
8.499966,111.1,-0.0009000,-0.03000
8.583299,111.1,-0.0009000,-0.03000
8.666632,111.1,-0.0009000,-0.03000
8.749965,111.1,-0.0008000,-0.02667
8.833298,111.0,-0.0008000,-0.02667
8.916631,111.0,-0.0008000,-0.02667
8.999964,111.0,-0.0008000,-0.02667
9.083297,111.0,-0.0008000,-0.02667
9.166630,111.0,-0.0007247,-0.02416
9.249963,111.0,-0.0007000,-0.02333
9.333296,111.0,-0.0007000,-0.02333
9.416629,110.9,-0.0007000,-0.02333
9.499962,110.9,-0.0007000,-0.02333
9.583295,110.9,-0.0007000,-0.02333
9.666628,110.9,-0.0006920,-0.02307
9.749961,110.9,-0.0006000,-0.02000
9.833294,110.9,-0.0006000,-0.02000
9.916627,110.8,-0.0006000,-0.02000
9.999960,110.8,-0.0005106,-0.01702
10.083293,110.9,0.0002613,0.008709
10.166626,112.0,0.002311,0.07704
10.249959,114.2,0.004421,0.1474
10.333292,117.3,0.006569,0.2190
10.416625,121.4,0.008616,0.2872
10.499958,126.2,0.01066,0.3554
10.583291,130.9,0.01271,0.4237
10.666624,135.4,0.01476,0.4919
10.749957,139.9,0.01691,0.5635
10.833290,144.4,0.01903,0.6343
10.916623,148.9,0.02110,0.7033
10.999956,153.5,0.02308,0.7693
11.083289,158.1,0.02515,0.8382
11.166622,162.7,0.02724,0.9079
11.249955,167.4,0.02933,0.9776
11.333288,172.1,0.03144,1.048
11.416621,176.9,0.03348,1.116
11.499954,181.7,0.03552,1.184
11.583287,186.5,0.03749,1.250
11.666620,191.2,0.03958,1.319
11.749953,195.8,0.04167,1.389
11.833286,200.3,0.04375,1.458
11.916619,205.1,0.04590,1.530
11.999952,210.0,0.04795,1.598
12.083285,215.1,0.04996,1.665
12.166618,220.4,0.05201,1.734
12.249951,225.8,0.05416,1.805
12.333284,231.2,0.05623,1.874
12.416617,236.7,0.05835,1.945
12.499950,242.2,0.06041,2.014
12.583283,247.8,0.06245,2.082
12.666616,253.4,0.06449,2.150
12.749949,259.0,0.06662,2.221
12.833282,264.7,0.06866,2.289
12.916615,270.5,0.07083,2.361
12.999948,276.3,0.07288,2.429
13.083281,282.2,0.07484,2.495
13.166614,288.0,0.07698,2.566
13.249947,293.9,0.07904,2.635
13.333280,299.9,0.08111,2.704
13.416613,305.9,0.08322,2.774
13.499946,312.0,0.08529,2.843
13.583279,318.1,0.08738,2.913
13.666612,324.2,0.08936,2.979
13.749945,330.4,0.09151,3.050
13.833278,336.5,0.09356,3.119
13.916611,342.8,0.09566,3.189
13.999944,349.0,0.09771,3.257
14.083277,355.3,0.09980,3.327
14.166610,361.6,0.1018,3.393
14.249943,367.9,0.1039,3.462
14.333276,374.3,0.1059,3.531
14.416609,380.7,0.1081,3.602
14.499942,387.1,0.1101,3.671
14.583275,393.6,0.1122,3.739
14.666608,400.1,0.1142,3.808
14.749941,406.7,0.1163,3.876
14.833274,413.2,0.1184,3.947
14.916607,419.8,0.1205,4.016
14.999940,426.5,0.1225,4.084
15.083273,433.3,0.1246,4.154
15.166606,440.0,0.1266,4.220
15.249939,446.7,0.1287,4.289
15.333272,453.5,0.1308,4.360
15.416605,460.4,0.1329,4.430
15.499938,467.2,0.1350,4.499
15.583271,474.2,0.1370,4.568
15.666604,481.2,0.1390,4.634
15.749937,488.1,0.1410,4.701
15.833270,495.1,0.1432,4.773
15.916603,502.2,0.1453,4.842
15.999936,509.3,0.1474,4.912
16.083269,516.5,0.1494,4.981
16.166602,523.8,0.1514,5.047
16.249935,531.0,0.1535,5.117
16.333268,538.2,0.1556,5.187
16.416601,545.5,0.1577,5.257
16.499934,552.7,0.1598,5.326
16.583267,560.1,0.1619,5.396
16.666600,567.5,0.1639,5.462
16.749933,574.8,0.1658,5.527
16.833266,582.2,0.1680,5.599
16.916599,589.7,0.1701,5.671
16.999932,597.1,0.1722,5.738
17.083265,604.6,0.1742,5.808
17.166598,612.1,0.1763,5.877
17.249931,619.6,0.1783,5.943
17.333264,627.2,0.1804,6.013
17.416597,634.7,0.1826,6.086
17.499930,642.4,0.1846,6.155
17.583263,650.0,0.1867,6.223
17.666596,657.7,0.1887,6.291
17.749929,665.3,0.1907,6.356
17.833262,672.9,0.1928,6.427
17.916595,680.5,0.1950,6.499
17.999928,688.1,0.1970,6.568
18.083261,695.8,0.1991,6.638
18.166594,703.6,0.2012,6.707
18.249927,711.3,0.2032,6.772
18.333260,718.9,0.2052,6.840
18.416593,726.6,0.2075,6.915
18.499926,734.2,0.2095,6.984
18.583259,741.9,0.2116,7.052
18.666592,749.6,0.2136,7.120
18.749925,757.4,0.2156,7.188
18.833258,765.0,0.2177,7.256
18.916591,772.6,0.2198,7.325
18.999924,780.2,0.2219,7.396
19.083257,787.8,0.2239,7.465
19.166590,795.5,0.2260,7.533
19.249923,803.3,0.2280,7.601
19.333256,810.9,0.2301,7.670
19.416589,818.4,0.2322,7.739
19.499922,825.9,0.2343,7.810
19.583255,833.4,0.2364,7.880
19.666588,840.9,0.2385,7.949
19.749921,848.4,0.2404,8.014
19.833254,855.8,0.2425,8.082
19.916587,863.1,0.2445,8.151
19.999920,870.3,0.2467,8.224
20.083253,877.6,0.2488,8.294
20.166586,884.7,0.2509,8.362
20.249919,891.8,0.2529,8.430
20.333252,898.9,0.2549,8.498
20.416585,905.7,0.2569,8.564
20.499918,912.4,0.2590,8.635
20.583251,919.1,0.2612,8.706
20.666584,925.7,0.2632,8.775
20.749917,932.1,0.2653,8.843
20.833250,938.4,0.2673,8.911
20.916583,944.4,0.2693,8.978
20.999916,950.2,0.2714,9.048
21.083249,955.8,0.2735,9.116
21.166582,961.3,0.2756,9.187
21.249915,966.5,0.2777,9.256
21.333248,971.4,0.2796,9.321
21.416581,976.0,0.2817,9.389
21.499914,980.2,0.2838,9.459
21.583247,984.3,0.2859,9.529
21.666580,988.0,0.2880,9.602
21.749913,991.4,0.2901,9.672
21.833246,994.4,0.2921,9.738
21.916579,997.1,0.2942,9.807
21.999912,999.4,0.2962,9.875
22.083245,1001,0.2984,9.946
22.166578,1003,0.3005,10.02
22.249911,1005,0.3025,10.08
22.333244,1006,0.3046,10.15
22.416577,1007,0.3066,10.22
22.499910,1007,0.3086,10.29
22.583243,1008,0.3108,10.36
22.666576,1008,0.3129,10.43
22.749909,1008,0.3150,10.50
22.833242,1008,0.3170,10.57
22.916575,1008,0.3191,10.64
22.999908,1007,0.3212,10.71
23.083241,1007,0.3233,10.78
23.166574,1007,0.3254,10.85
23.249907,1006,0.3274,10.91
23.333240,1006,0.3295,10.98
23.416573,1005,0.3315,11.05
23.499906,1004,0.3336,11.12
23.583239,1003,0.3357,11.19
23.666572,1003,0.3377,11.26
23.749905,1002,0.3399,11.33
23.833238,1001,0.3420,11.40
23.916571,999.9,0.3439,11.46
23.999904,998.9,0.3460,11.53
24.083237,997.9,0.3481,11.60
24.166570,996.9,0.3502,11.67
24.249903,995.8,0.3523,11.74
24.333236,994.7,0.3544,11.81
24.416569,993.6,0.3564,11.88
24.499902,992.4,0.3585,11.95
24.583235,991.1,0.3605,12.02
24.666568,989.9,0.3626,12.09
24.749901,988.6,0.3646,12.15
24.833234,987.3,0.3668,12.23
24.916567,986.0,0.3688,12.29
24.999900,984.5,0.3708,12.36
25.083233,983.1,0.3729,12.43
25.166566,981.7,0.3750,12.50
25.249899,980.2,0.3771,12.57
25.333232,978.7,0.3791,12.64
25.416565,977.2,0.3812,12.71
25.499898,975.6,0.3832,12.77
25.583231,974.0,0.3853,12.84
25.666564,972.4,0.3874,12.91
25.749897,970.8,0.3895,12.98
25.833230,969.1,0.3915,13.05
25.916563,967.5,0.3937,13.12
25.999896,965.8,0.3957,13.19
26.083229,964.1,0.3977,13.26
26.166562,962.3,0.3999,13.33
26.249895,960.7,0.4019,13.40
26.333228,958.9,0.4040,13.47
26.416561,957.2,0.4061,13.54
26.499894,955.5,0.4081,13.60
26.583227,953.7,0.4101,13.67
26.666560,951.9,0.4122,13.74
26.749893,950.2,0.4143,13.81
26.833226,948.4,0.4164,13.88
26.916559,946.6,0.4185,13.95
26.999892,944.9,0.4205,14.02
27.083225,943.0,0.4225,14.08
27.166558,941.2,0.4246,14.15
27.249891,939.4,0.4268,14.23
27.333224,937.6,0.4288,14.29
27.416557,935.8,0.4308,14.36
27.499890,934.0,0.4329,14.43
27.583223,932.1,0.4350,14.50
27.666556,930.3,0.4370,14.57
27.749889,928.6,0.4392,14.64
27.833222,926.8,0.4412,14.71
27.916555,924.9,0.4433,14.78
27.999888,923.2,0.4454,14.85
28.083221,921.3,0.4473,14.91
28.166554,919.4,0.4494,14.98
28.249887,917.7,0.4516,15.05
28.333220,915.9,0.4536,15.12
28.416553,914.1,0.4557,15.19
28.499886,912.3,0.4578,15.26
28.583219,910.4,0.4597,15.32
28.666552,908.5,0.4618,15.39
28.749885,906.8,0.4640,15.47
28.833218,905.0,0.4660,15.53
28.916551,903.2,0.4681,15.60
28.999884,901.4,0.4702,15.67
29.083217,899.6,0.4721,15.74
29.166550,897.7,0.4742,15.81
29.249883,895.9,0.4764,15.88
29.333216,894.1,0.4785,15.95
29.416549,892.3,0.4805,16.02
29.499882,890.5,0.4827,16.09
29.583215,888.7,0.4846,16.15
29.666548,886.8,0.4867,16.22
29.749881,884.9,0.4888,16.29
29.833214,883.1,0.4909,16.36
29.916547,881.3,0.4930,16.43
29.999880,879.5,0.4951,16.50
30.083213,877.7,0.4971,16.57
30.166546,875.8,0.4991,16.64
30.249879,873.9,0.5012,16.71
30.333212,872.1,0.5034,16.78
30.416545,870.3,0.5054,16.85
30.499878,868.5,0.5075,16.92
30.583211,866.7,0.5095,16.98
30.666544,864.7,0.5115,17.05
30.749877,862.8,0.5136,17.12
30.833210,861.0,0.5157,17.19
30.916543,859.2,0.5178,17.26
30.999876,857.4,0.5199,17.33
31.083209,855.5,0.5220,17.40
31.166542,853.6,0.5239,17.46
31.249875,851.6,0.5259,17.53
31.333208,849.7,0.5281,17.60
31.416541,847.9,0.5302,17.67
31.499874,846.1,0.5323,17.74
31.583207,844.2,0.5344,17.81
31.666540,842.3,0.5364,17.88
31.749873,840.3,0.5384,17.95
31.833206,838.3,0.5406,18.02
31.916539,836.5,0.5427,18.09
31.999872,834.6,0.5448,18.16
32.083205,832.7,0.5469,18.23
32.166538,830.7,0.5488,18.29
32.249871,828.7,0.5509,18.36
32.333204,826.7,0.5529,18.43
32.416537,824.8,0.5550,18.50
32.499870,822.9,0.5572,18.57
32.583203,820.9,0.5592,18.64
32.666536,819.0,0.5612,18.71
32.749869,817.0,0.5633,18.78
32.833202,814.9,0.5653,18.84
32.916535,813.0,0.5674,18.91
32.999868,811.0,0.5696,18.99
33.083201,809.0,0.5716,19.05
33.166534,807.1,0.5737,19.12
33.249867,805.0,0.5756,19.19
33.333200,802.9,0.5777,19.26
33.416533,800.9,0.5799,19.33
33.499866,798.8,0.5819,19.40
33.583199,796.8,0.5841,19.47
33.666532,794.8,0.5861,19.54
33.749865,792.7,0.5881,19.60
33.833198,790.5,0.5902,19.67
33.916531,788.4,0.5923,19.74
33.999864,786.3,0.5943,19.81
34.083197,784.2,0.5964,19.88
34.166530,782.1,0.5986,19.95
34.249863,780.0,0.6006,20.02
34.333196,777.8,0.6026,20.09
34.416529,775.6,0.6047,20.16
34.499862,773.5,0.6068,20.23
34.583195,771.3,0.6089,20.30
34.666528,769.1,0.6109,20.36
34.749861,767.0,0.6130,20.43
34.833194,764.7,0.6150,20.50
34.916527,762.4,0.6171,20.57
34.999860,760.2,0.6192,20.64
35.083193,758.0,0.6213,20.71
35.166526,755.7,0.6234,20.78
35.249859,753.5,0.6255,20.85
35.333192,751.2,0.6274,20.91
35.416525,748.9,0.6295,20.98
35.499858,746.6,0.6316,21.05
35.583191,744.3,0.6337,21.12
35.666524,741.9,0.6357,21.19
35.749857,739.6,0.6379,21.26
35.833190,737.2,0.6399,21.33
35.916523,734.8,0.6419,21.40
35.999856,732.4,0.6440,21.47
36.083189,730.0,0.6461,21.54
36.166522,727.6,0.6481,21.60
36.249855,725.2,0.6503,21.68
36.333188,722.8,0.6523,21.74
36.416521,720.3,0.6544,21.81
36.499854,717.8,0.6565,21.88
36.583187,715.3,0.6586,21.95
36.666520,712.8,0.6606,22.02
36.749853,710.3,0.6627,22.09
36.833186,707.7,0.6647,22.16
36.916519,705.1,0.6668,22.23
36.999852,702.6,0.6689,22.30
37.083185,700.0,0.6709,22.36
37.166518,697.4,0.6731,22.44
37.249851,694.8,0.6752,22.51
37.333184,692.1,0.6771,22.57
37.416517,689.4,0.6792,22.64
37.499850,686.7,0.6813,22.71
37.583183,684.0,0.6834,22.78
37.666516,681.3,0.6855,22.85
37.749849,678.5,0.6875,22.92
37.833182,675.8,0.6896,22.99
37.916515,672.9,0.6916,23.05
37.999848,670.0,0.6937,23.12
38.083181,667.2,0.6958,23.19
38.166514,664.3,0.6979,23.26
38.249847,661.4,0.7000,23.33
38.333180,658.6,0.7020,23.40
38.416513,655.6,0.7040,23.47
38.499846,652.6,0.7061,23.54
38.583179,649.6,0.7083,23.61
38.666512,646.6,0.7103,23.68
38.749845,643.5,0.7123,23.74
38.833178,640.4,0.7144,23.81
38.916511,637.2,0.7163,23.88
38.999844,634.1,0.7185,23.95
39.083177,630.9,0.7207,24.02
39.166510,627.6,0.7227,24.09
39.249843,624.3,0.7248,24.16
39.333176,621.0,0.7269,24.23
39.416509,617.5,0.7288,24.29
39.499842,614.0,0.7308,24.36
39.583175,610.6,0.7331,24.44
39.666508,607.0,0.7351,24.50
39.749841,603.3,0.7372,24.57
39.833174,599.5,0.7392,24.64
39.916507,595.6,0.7413,24.71
39.999840,591.6,0.7433,24.78
40.083173,587.5,0.7454,24.85
40.166506,583.4,0.7476,24.92
40.249839,579.1,0.7496,24.99
40.333172,574.4,0.7517,25.06
40.416505,569.3,0.7537,25.12
40.499838,563.3,0.7558,25.19
40.583171,516.8,0.7582,25.27
40.666504,403.2,0.7602,25.34
40.749837,289.6,0.7623,25.41
40.833170,176.5,0.7642,25.47