File: CallibrationData/TiniusOlsen/AL7075_2.csv
Time (sec),Stress (MPa),Position (mm),Strain From Position (%)
0.083333,37.98,0.05280,1.760
0.166666,37.95,0.05280,1.760
0.249999,37.92,0.05280,1.760
0.333332,38.04,0.05391,1.797
0.416665,38.78,0.05606,1.869
0.499998,40.19,0.05838,1.946
0.583331,42.11,0.06048,2.016
0.666664,44.41,0.06264,2.088
0.749997,47.06,0.06477,2.159
0.833330,49.50,0.06696,2.232
0.916663,51.76,0.06910,2.303
0.999996,53.95,0.07114,2.371
1.083329,56.13,0.07323,2.441
1.166662,58.29,0.07524,2.508
1.249995,60.40,0.07729,2.576
1.333328,62.54,0.07941,2.647
1.416661,64.68,0.08154,2.718
1.499994,66.85,0.08366,2.789
1.583327,69.05,0.08568,2.856
1.666660,71.22,0.08770,2.923
1.749993,73.35,0.08972,2.991
1.833326,75.48,0.09193,3.064
1.916659,77.54,0.09396,3.132
1.999992,79.49,0.09608,3.203
2.083325,81.09,0.09813,3.271
2.166658,82.29,0.1002,3.339
2.249991,83.10,0.1021,3.405
2.333324,83.46,0.1043,3.476
2.416657,83.53,0.1064,3.546
2.499990,83.51,0.1085,3.617
2.583323,83.48,0.1106,3.686
2.666656,83.46,0.1126,3.752
2.749989,83.44,0.1146,3.820
2.833322,83.43,0.1167,3.890
2.916655,83.44,0.1188,3.961
2.999988,83.45,0.1209,4.031
3.083321,83.47,0.1230,4.101
3.166654,83.49,0.1251,4.169
3.249987,83.52,0.1271,4.237
3.333320,83.53,0.1292,4.306
3.416653,83.55,0.1313,4.377
3.499986,83.54,0.1334,4.447
3.583319,83.53,0.1355,4.516
3.666652,83.52,0.1375,4.584
3.749985,83.51,0.1395,4.651
3.833318,83.50,0.1416,4.719
3.916651,83.54,0.1437,4.791
3.999984,83.60,0.1458,4.860
4.083317,83.70,0.1479,4.931
4.166650,83.79,0.1500,4.999
4.249983,83.87,0.1520,5.065
4.333316,83.94,0.1540,5.133
4.416649,83.97,0.1561,5.203
4.499982,83.98,0.1582,5.274
4.583315,84.00,0.1603,5.343
4.666648,84.02,0.1624,5.414
4.749981,84.05,0.1644,5.480
4.833314,84.10,0.1664,5.548
4.916647,84.15,0.1685,5.618
4.999980,84.20,0.1706,5.685
5.083313,84.27,0.1727,5.756
5.166646,84.34,0.1748,5.826
5.249979,84.41,0.1768,5.894
5.333312,84.47,0.1789,5.962
5.416645,84.52,0.1810,6.033
5.499978,84.55,0.1831,6.103
5.583311,84.56,0.1852,6.173
5.666644,84.55,0.1872,6.241
5.749977,84.54,0.1893,6.309
5.833310,84.53,0.1913,6.378
5.916643,84.52,0.1934,6.446
5.999976,84.50,0.1955,6.516
6.083309,84.49,0.1976,6.585
6.166642,84.48,0.1997,6.655
6.249975,84.46,0.2017,6.724
6.333308,84.44,0.2038,6.792
6.416641,84.42,0.2058,6.860
6.499974,84.40,0.2079,6.931
6.583307,84.37,0.2101,7.002
6.666640,84.35,0.2121,7.071
6.749973,84.34,0.2142,7.139
6.833306,84.32,0.2162,7.206
6.916639,84.30,0.2182,7.275
6.999972,84.29,0.2204,7.345
7.083305,84.27,0.2224,7.413
7.166638,84.25,0.2245,7.483
7.249971,84.25,0.2265,7.551
7.333304,84.26,0.2286,7.620
7.416637,84.32,0.2306,7.688
7.499970,84.53,0.2327,7.757
7.583303,85.10,0.2348,7.827
7.666636,86.15,0.2369,7.898
7.749969,87.73,0.2390,7.966
7.833302,89.82,0.2410,8.034
7.916635,92.39,0.2429,8.096
7.999968,95.13,-0.008727,-0.2909
8.083301,98.42,-0.004515,-0.1505
8.166634,102.0,-0.003166,-0.1055
8.249967,105.2,-0.002700,-0.09001
8.333300,107.8,-0.002387,-0.07957
8.416633,109.9,-0.002148,-0.07159
8.499966,110.9,-0.001961,-0.06536
8.583299,111.2,-0.001898,-0.06326
8.666632,111.3,-0.001735,-0.05782
8.749965,111.3,-0.001671,-0.05572
8.833298,111.4,-0.001600,-0.05333
8.916631,111.4,-0.001500,-0.05000
8.999964,111.4,-0.001482,-0.04941
9.083297,111.4,-0.001400,-0.04667
9.166630,111.4,-0.001400,-0.04667
9.249963,111.4,-0.001300,-0.04333
9.333296,111.4,-0.001300,-0.04333
9.416629,111.4,-0.001300,-0.04333
9.499962,111.4,-0.001204,-0.04012
9.583295,111.4,-0.001200,-0.04000
9.666628,111.3,-0.001200,-0.04000
9.749961,111.3,-0.001200,-0.04000
9.833294,111.3,-0.001151,-0.03837
9.916627,111.3,-0.001100,-0.03667
9.999960,111.3,-0.001100,-0.03667
10.083293,111.2,-0.001100,-0.03667
10.166626,111.2,-0.001100,-0.03667
10.249959,111.2,-0.001100,-0.03667
10.333292,111.2,-0.001100,-0.03667
10.416625,111.1,-0.001100,-0.03667
10.499958,111.1,-0.001000,-0.03333
10.583291,111.1,-0.001000,-0.03333
10.666624,111.1,-0.001000,-0.03333
10.749957,111.0,-0.001000,-0.03333
10.833290,111.0,-0.001000,-0.03333
10.916623,111.0,-0.001000,-0.03333
10.999956,111.0,-0.001000,-0.03333
11.083289,110.9,-0.001000,-0.03333
11.166622,110.9,-0.001000,-0.03333
11.249955,110.9,-0.0003919,-0.01306
11.333288,111.3,0.0009077,0.03026
11.416621,112.6,0.003032,0.1011
11.499954,114.6,0.005201,0.1734
11.583287,117.4,0.007314,0.2438
11.666620,120.8,0.009411,0.3137
11.749953,124.4,0.01145,0.3816
11.833286,127.8,0.01350,0.4499
11.916619,131.2,0.01557,0.5190
11.999952,134.6,0.01772,0.5908
12.083285,138.0,0.01980,0.6599
12.166618,141.4,0.02191,0.7302
12.249951,144.9,0.02394,0.7980
12.333284,148.3,0.02594,0.8647
12.416617,151.7,0.02805,0.9351
12.499950,155.1,0.03017,1.006
12.583283,158.6,0.03226,1.075
12.666616,162.1,0.03430,1.143
12.749949,165.6,0.03637,1.212
12.833282,169.2,0.03836,1.279
12.916615,172.7,0.04044,1.348
12.999948,176.3,0.04258,1.419
13.083281,179.9,0.04467,1.489
13.166614,183.5,0.04678,1.559
13.249947,187.1,0.04882,1.627
13.333280,190.8,0.05082,1.694
13.416613,194.5,0.05288,1.763
13.499946,198.3,0.05500,1.833
13.583279,202.0,0.05715,1.905
13.666612,205.7,0.05916,1.972
13.749945,209.5,0.06128,2.043
13.833278,213.2,0.06325,2.108
13.916611,216.9,0.06528,2.176
13.999944,220.6,0.06733,2.244
14.083277,224.3,0.06951,2.317
14.166610,228.0,0.07162,2.387
14.249943,231.7,0.07366,2.455
14.333276,235.4,0.07570,2.523
14.416609,239.2,0.07769,2.590
14.499942,242.8,0.07974,2.658
14.583275,246.5,0.08192,2.731
14.666608,250.2,0.08397,2.799
14.749941,253.9,0.08607,2.869
14.833274,257.7,0.08814,2.938
14.916607,261.4,0.09017,3.006
14.999940,265.1,0.09218,3.073
15.083273,268.8,0.09430,3.143
15.166606,272.4,0.09641,3.214
15.249939,276.1,0.09853,3.284
15.333272,279.8,0.1006,3.353
15.416605,283.4,0.1026,3.418
15.499938,287.0,0.1046,3.486
15.583271,290.6,0.1067,3.558
15.666604,294.1,0.1088,3.627
15.749937,297.6,0.1109,3.697
15.833270,301.2,0.1130,3.765
15.916603,304.7,0.1150,3.832
15.999936,308.1,0.1170,3.901
16.083269,311.5,0.1191,3.969
16.166602,314.9,0.1212,4.039
16.249935,318.2,0.1233,4.110
16.333268,321.6,0.1254,4.180
16.416601,324.9,0.1274,4.247
16.499934,328.3,0.1294,4.314
16.583267,331.6,0.1315,4.382
16.666600,334.9,0.1337,4.455
16.749933,338.1,0.1358,4.526
16.833266,341.3,0.1379,4.595
16.916599,344.6,0.1399,4.663
16.999932,347.7,0.1419,4.730
17.083265,350.9,0.1439,4.798
17.166598,354.0,0.1461,4.868
17.249931,357.1,0.1481,4.938
17.333264,360.2,0.1503,5.009
17.416597,363.3,0.1523,5.078
17.499930,366.4,0.1544,5.146
17.583263,369.4,0.1564,5.212
17.666596,372.3,0.1585,5.284
17.749929,375.2,0.1606,5.352
17.833262,378.2,0.1627,5.424
17.916595,381.1,0.1648,5.492
17.999928,384.0,0.1668,5.560
18.083261,386.8,0.1688,5.627
18.166594,389.5,0.1710,5.700
18.249927,392.2,0.1730,5.768
18.333260,394.9,0.1751,5.838
18.416593,397.6,0.1773,5.908
18.499926,400.1,0.1792,5.973
18.583259,402.6,0.1813,6.043
18.666592,405.1,0.1834,6.113
18.749925,407.5,0.1855,6.182
18.833258,409.8,0.1875,6.251
18.916591,412.1,0.1896,6.321
18.999924,414.3,0.1917,6.390
19.083257,416.4,0.1937,6.456
19.166590,418.5,0.1958,6.526
19.249923,420.4,0.1979,6.595
19.333256,422.3,0.2000,6.666
19.416589,424.2,0.2020,6.734
19.499922,425.9,0.2041,6.804
19.583255,427.6,0.2061,6.872
19.666588,429.2,0.2082,6.939
19.749921,430.8,0.2103,7.009
19.833254,432.3,0.2123,7.078
19.916587,433.8,0.2145,7.149
19.999920,435.3,0.2165,7.217
20.083253,436.7,0.2185,7.284
20.166586,438.1,0.2206,7.355
20.249919,439.5,0.2227,7.424
20.333252,440.8,0.2248,7.492
20.416585,442.1,0.2269,7.563
20.499918,443.4,0.2290,7.632
20.583251,444.7,0.2309,7.697
20.666584,445.9,0.2330,7.768
20.749917,447.2,0.2351,7.838
20.833250,448.4,0.2372,7.905
20.916583,449.6,0.2392,7.975
20.999916,450.7,0.2413,8.045
21.083249,451.9,0.2434,8.113
21.166582,453.0,0.2454,8.180
21.249915,454.2,0.2475,8.251
21.333248,455.3,0.2496,8.320
21.416581,456.4,0.2517,8.390
21.499914,457.5,0.2538,8.459
21.583247,458.5,0.2558,8.527
21.666580,459.6,0.2579,8.595
21.749913,460.6,0.2599,8.664
21.833246,461.7,0.2620,8.734
21.916579,462.7,0.2641,8.804
21.999912,463.7,0.2662,8.872
22.083245,464.7,0.2682,8.940
22.166578,465.7,0.2703,9.009
22.249911,466.7,0.2723,9.077
22.333244,467.7,0.2745,9.149
22.416577,468.7,0.2765,9.217
22.499910,469.6,0.2786,9.285
22.583243,470.6,0.2806,9.354
22.666576,471.5,0.2827,9.422
22.749909,472.4,0.2847,9.492
22.833242,473.3,0.2869,9.562
22.916575,474.3,0.2889,9.630
22.999908,475.2,0.2910,9.700
23.083241,476.1,0.2930,9.768
23.166574,477.0,0.2951,9.835
23.249907,477.8,0.2972,9.905
23.333240,478.7,0.2993,9.976
23.416573,479.6,0.3014,10.05
23.499906,480.4,0.3034,10.11
23.583239,481.3,0.3055,10.18
23.666572,482.1,0.3074,10.25
23.749905,482.9,0.3096,10.32
23.833238,483.8,0.3117,10.39
23.916571,484.6,0.3138,10.46
23.999904,485.5,0.3159,10.53
24.083237,486.3,0.3179,10.60
24.166570,487.1,0.3199,10.66
24.249903,487.9,0.3219,10.73
24.333236,488.7,0.3241,10.80
24.416569,489.5,0.3262,10.87
24.499902,490.3,0.3283,10.94
24.583235,491.1,0.3303,11.01
24.666568,491.9,0.3323,11.08
24.749901,492.6,0.3344,11.15
24.833234,493.4,0.3365,11.22
24.916567,494.2,0.3386,11.29
24.999900,495.0,0.3407,11.36
25.083233,495.8,0.3428,11.43
25.166566,496.5,0.3448,11.49
25.249899,497.2,0.3468,11.56
25.333232,497.9,0.3489,11.63
25.416565,498.7,0.3510,11.70
25.499898,499.4,0.3531,11.77
25.583231,500.2,0.3553,11.84
25.666564,500.9,0.3572,11.91
25.749897,501.6,0.3593,11.98
25.833230,502.3,0.3613,12.04
25.916563,503.0,0.3635,12.12
25.999896,503.7,0.3655,12.18
26.083229,504.5,0.3676,12.25
26.166562,505.2,0.3697,12.32
26.249895,505.9,0.3717,12.39
26.333228,506.5,0.3737,12.46
26.416561,507.1,0.3759,12.53
26.499894,507.9,0.3780,12.60
26.583227,508.5,0.3800,12.67
26.666560,509.3,0.3821,12.74
26.749893,509.9,0.3841,12.80
26.833226,510.3,0.3861,12.87
26.916559,510.6,0.3883,12.94
26.999892,511.1,0.3904,13.01
27.083225,511.7,0.3925,13.08
27.166558,512.4,0.3945,13.15
27.249891,513.2,0.3965,13.22
27.333224,514.1,0.3986,13.29
27.416557,514.9,0.4007,13.36
27.499890,515.5,0.4028,13.43
27.583223,516.2,0.4049,13.50
27.666556,516.8,0.4070,13.57
27.749889,517.4,0.4090,13.63
27.833222,518.0,0.4110,13.70
27.916555,518.6,0.4130,13.77
27.999888,519.2,0.4152,13.84
28.083221,519.8,0.4173,13.91
28.166554,520.4,0.4194,13.98
28.249887,521.0,0.4214,14.05
28.333220,521.6,0.4234,14.11
28.416553,522.1,0.4254,14.18
28.499886,522.7,0.4276,14.25
28.583219,523.3,0.4297,14.32
28.666552,523.9,0.4318,14.39
28.749885,524.6,0.4338,14.46
28.833218,525.2,0.4358,14.53
28.916551,525.7,0.4378,14.59
28.999884,526.2,0.4400,14.67
29.083217,526.8,0.4420,14.73
29.166550,527.4,0.4441,14.80
29.249883,528.0,0.4462,14.87
29.333216,528.6,0.4482,14.94
29.416549,529.1,0.4503,15.01
29.499882,529.6,0.4524,15.08
29.583215,530.2,0.4544,15.15
29.666548,530.7,0.4565,15.22
29.749881,531.3,0.4587,15.29
29.833214,531.9,0.4607,15.36
29.916547,532.3,0.4627,15.42
29.999880,532.9,0.4648,15.49
30.083213,533.4,0.4668,15.56
30.166546,533.9,0.4690,15.63
30.249879,534.5,0.4711,15.70
30.333212,535.0,0.4731,15.77
30.416545,535.5,0.4752,15.84
30.499878,536.0,0.4773,15.91
30.583211,536.5,0.4793,15.98
30.666544,537.0,0.4815,16.05
30.749877,537.5,0.4835,16.12
30.833210,538.1,0.4855,16.18
30.916543,538.5,0.4875,16.25
30.999876,539.0,0.4897,16.32
31.083209,539.5,0.4917,16.39
31.166542,540.0,0.4939,16.46
31.249875,540.5,0.4959,16.53
31.333208,541.0,0.4980,16.60
31.416541,541.4,0.5001,16.67
31.499874,541.9,0.5021,16.74
31.583207,542.3,0.5042,16.81
31.666540,542.8,0.5063,16.88
31.749873,543.2,0.5083,16.94
31.833206,543.7,0.5104,17.01
31.916539,544.2,0.5125,17.08
31.999872,544.6,0.5145,17.15
32.083205,545.1,0.5166,17.22
32.166538,545.5,0.5187,17.29
32.249871,546.0,0.5208,17.36
32.333204,546.4,0.5229,17.43
32.416537,546.9,0.5249,17.50
32.499870,547.3,0.5270,17.57
32.583203,547.7,0.5290,17.63
32.666536,548.2,0.5312,17.71
32.749869,548.6,0.5332,17.77
32.833202,549.1,0.5353,17.84
32.916535,549.5,0.5373,17.91
32.999868,549.9,0.5394,17.98
33.083201,550.3,0.5414,18.05
33.166534,550.8,0.5436,18.12
33.249867,551.2,0.5456,18.19
33.333200,551.6,0.5477,18.26
33.416533,552.0,0.5498,18.33
33.499866,552.4,0.5518,18.39
33.583199,552.7,0.5539,18.46
33.666532,553.2,0.5560,18.53
33.749865,553.6,0.5581,18.60
33.833198,554.0,0.5601,18.67
33.916531,554.4,0.5622,18.74
33.999864,554.8,0.5642,18.81
34.083197,555.1,0.5663,18.88
34.166530,555.5,0.5684,18.95
34.249863,556.0,0.5705,19.02
34.333196,556.3,0.5725,19.08
34.416529,556.7,0.5746,19.15
34.499862,557.1,0.5766,19.22
34.583195,557.4,0.5787,19.29
34.666528,557.8,0.5808,19.36
34.749861,558.2,0.5829,19.43
34.833194,558.6,0.5850,19.50
34.916527,559.0,0.5870,19.57
34.999860,559.4,0.5890,19.63
35.083193,559.6,0.5910,19.70
35.166526,560.0,0.5932,19.77
35.249859,560.4,0.5953,19.84
35.333192,560.7,0.5974,19.91
35.416525,561.1,0.5995,19.98
35.499858,561.5,0.6015,20.05
35.583191,561.8,0.6035,20.12
35.666524,562.1,0.6056,20.19
35.749857,562.4,0.6078,20.26
35.833190,562.8,0.6099,20.33
35.916523,563.2,0.6120,20.40
35.999856,563.5,0.6139,20.46
36.083189,563.7,0.6159,20.53
36.166522,564.0,0.6180,20.60
36.249855,564.3,0.6201,20.67
36.333188,564.6,0.6222,20.74
36.416521,565.0,0.6243,20.81
36.499854,565.4,0.6264,20.88
36.583187,565.7,0.6283,20.94
36.666520,565.9,0.6304,21.01
36.749853,566.2,0.6325,21.08
36.833186,566.6,0.6346,21.15
36.916519,566.9,0.6367,21.22
36.999852,567.3,0.6387,21.29
37.083185,567.6,0.6407,21.36
37.166518,567.8,0.6427,21.42
37.249851,568.1,0.6449,21.50
37.333184,568.5,0.6470,21.57
37.416517,568.8,0.6491,21.64
37.499850,569.1,0.6511,21.70
37.583183,569.4,0.6532,21.77
37.666516,569.6,0.6552,21.84
37.749849,569.9,0.6573,21.91
37.833182,570.2,0.6594,21.98
37.916515,570.5,0.6615,22.05
37.999848,570.8,0.6636,22.12
38.083181,571.1,0.6656,22.19
38.166514,571.4,0.6676,22.25
38.249847,571.6,0.6697,22.32
38.333180,571.8,0.6718,22.39
38.416513,572.1,0.6739,22.46
38.499846,572.5,0.6759,22.53
38.583179,572.8,0.6780,22.60
38.666512,573.0,0.6799,22.66
38.749845,573.2,0.6820,22.73
38.833178,573.4,0.6840,22.80
38.916511,573.7,0.6861,22.87
38.999844,574.0,0.6883,22.94
39.083177,574.3,0.6903,23.01
39.166510,574.6,0.6923,23.08
39.249843,574.9,0.6944,23.15
39.333176,575.1,0.6965,23.22
39.416509,575.3,0.6987,23.29
39.499842,575.6,0.7008,23.36
39.583175,575.9,0.7029,23.43
39.666508,576.1,0.7048,23.49
39.749841,576.3,0.7069,23.56
39.833174,576.5,0.7090,23.63
39.916507,576.7,0.7110,23.70
39.999840,577.0,0.7132,23.77
40.083173,577.3,0.7153,23.84
40.166506,577.5,0.7173,23.91
40.249839,577.7,0.7193,23.98
40.333172,578.0,0.7215,24.05
40.416505,578.2,0.7235,24.12
40.499838,578.4,0.7256,24.19
40.583171,578.6,0.7277,24.26
40.666504,578.9,0.7298,24.33
40.749837,579.1,0.7318,24.39
40.833170,579.3,0.7339,24.46
40.916503,579.5,0.7359,24.53
40.999836,579.7,0.7380,24.60
41.083169,579.9,0.7401,24.67
41.166502,580.2,0.7422,24.74
41.249835,580.3,0.7442,24.81
41.333168,580.5,0.7463,24.88
41.416501,580.7,0.7484,24.95
41.499834,580.9,0.7505,25.02
41.583167,581.1,0.7525,25.08
41.666500,581.3,0.7546,25.15
41.749833,581.4,0.7566,25.22
41.833166,581.6,0.7587,25.29
41.916499,581.8,0.7608,25.36
41.999832,581.9,0.7629,25.43
42.083165,582.1,0.7650,25.50
42.166498,582.3,0.7670,25.57
42.249831,582.5,0.7691,25.64
42.333164,582.6,0.7711,25.70
42.416497,582.8,0.7732,25.77
42.499830,582.9,0.7753,25.84
42.583163,583.1,0.7774,25.91
42.666496,583.3,0.7795,25.98
42.749829,583.5,0.7815,26.05
42.833162,583.7,0.7835,26.12
42.916495,583.8,0.7856,26.19
42.999828,584.0,0.7877,26.26
43.083161,584.2,0.7898,26.33
43.166494,584.3,0.7919,26.40
43.249827,584.5,0.7939,26.46
43.333160,584.6,0.7960,26.53
43.416493,584.8,0.7981,26.60
43.499826,584.9,0.8001,26.67
43.583159,585.1,0.8023,26.74
43.666492,585.3,0.8043,26.81
43.749825,585.4,0.8063,26.88
43.833158,585.5,0.8084,26.95
43.916491,585.6,0.8104,27.01
43.999824,585.8,0.8126,27.09
44.083157,585.9,0.8146,27.15
44.166490,586.1,0.8167,27.22
44.249823,586.2,0.8188,27.29
44.333156,586.3,0.8208,27.36
44.416489,586.4,0.8228,27.43
44.499822,586.5,0.8249,27.50
44.583155,586.6,0.8270,27.57
44.666488,586.7,0.8291,27.64
44.749821,586.8,0.8312,27.71
44.833154,586.9,0.8332,27.77
44.916487,586.9,0.8353,27.84
44.999820,587.0,0.8374,27.91
45.083153,587.2,0.8395,27.98
45.166486,587.3,0.8415,28.05
45.249819,587.4,0.8436,28.12
45.333152,587.5,0.8456,28.19
45.416485,587.5,0.8477,28.26
45.499818,587.6,0.8498,28.33
45.583151,587.7,0.8519,28.40
45.666484,587.8,0.8540,28.47
45.749817,587.9,0.8561,28.54
45.833150,588.0,0.8580,28.60
45.916483,588.0,0.8601,28.67
45.999816,588.1,0.8622,28.74
46.083149,588.2,0.8644,28.81
46.166482,588.3,0.8664,28.88
46.249815,588.4,0.8685,28.95
46.333148,588.5,0.8704,29.01
46.416481,588.6,0.8724,29.08
46.499814,588.6,0.8745,29.15
46.583147,588.7,0.8767,29.22
46.666480,588.8,0.8788,29.29
46.749813,588.9,0.8809,29.36
46.833146,589.0,0.8829,29.43
46.916479,589.0,0.8849,29.50
46.999812,589.0,0.8870,29.57
47.083145,589.0,0.8891,29.64
47.166478,589.0,0.8912,29.71
47.249811,589.0,0.8934,29.78
47.333144,589.1,0.8954,29.85
47.416477,589.0,0.8974,29.91
47.499810,588.9,0.8995,29.98
47.583143,588.9,0.9016,30.05
47.666476,588.9,0.9037,30.12
47.749809,588.9,0.9057,30.19
47.833142,588.9,0.9079,30.26
47.916475,588.8,0.9098,30.33
47.999808,588.7,0.9119,30.40
48.083141,588.6,0.9140,30.47
48.166474,588.6,0.9161,30.54
48.249807,588.5,0.9182,30.61
48.333140,588.4,0.9202,30.67
48.416473,588.3,0.9223,30.74
48.499806,588.1,0.9243,30.81
48.583139,587.9,0.9264,30.88
48.666472,587.8,0.9285,30.95
48.749805,587.7,0.9306,31.02
48.833138,587.6,0.9327,31.09
48.916471,587.4,0.9347,31.16
48.999804,587.1,0.9368,31.23
49.083137,586.8,0.9388,31.29
49.166470,586.6,0.9410,31.37
49.249803,586.4,0.9431,31.44
49.333136,586.2,0.9451,31.50
49.416469,586.0,0.9472,31.57
49.499802,585.7,0.9492,31.64
49.583135,585.3,0.9513,31.71
49.666468,585.0,0.9534,31.78
49.749801,584.7,0.9555,31.85
49.833134,584.3,0.9576,31.92
49.916467,583.8,0.9596,31.99
49.999800,583.1,0.9616,32.05
50.083133,582.4,0.9636,32.12
50.166466,581.6,0.9658,32.19
50.249799,581.0,0.9679,32.26
50.333132,580.4,0.9700,32.33
50.416465,579.8,0.9720,32.40
50.499798,579.1,0.9740,32.47
50.583131,578.2,0.9761,32.54
50.666464,577.4,0.9781,32.60
50.749797,576.5,0.9802,32.67
50.833130,575.4,0.9824,32.75
50.916463,519.0,0.9849,32.83
50.999796,403.4,0.9867,32.89
51.083129,287.1,0.9887,32.96
51.166462,170.8,0.9907,33.02
51.249795,54.69,0.9927,33.09