File: CallibrationData/TiniusOlsen/C1008_4.csv
Time (sec),Stress (MPa),Position (mm),Strain From Position (%)
0.083333,64.25,0.08410,2.803
0.166666,64.23,0.08410,2.803
0.249999,64.20,0.08410,2.803
0.333332,64.29,0.08473,2.824
0.416665,65.00,0.08658,2.886
0.499998,66.54,0.08884,2.961
0.583331,68.73,0.09104,3.035
0.666664,71.47,0.09320,3.107
0.749997,74.52,0.09529,3.176
0.833330,77.29,0.09747,3.249
0.916663,79.51,0.09960,3.320
0.999996,81.19,0.1017,3.391
1.083329,82.41,0.1038,3.461
1.166662,83.22,0.1059,3.530
1.249995,83.68,0.1079,3.595
1.333328,83.88,0.1100,3.665
1.416661,84.00,0.1121,3.736
1.499994,84.08,0.1142,3.805
1.583327,84.13,0.1162,3.874
1.666660,84.18,0.1183,3.943
1.749993,84.23,0.1204,4.012
1.833326,84.28,0.1224,4.081
1.916659,84.32,0.1246,4.153
1.999992,84.36,0.1267,4.222
2.083325,84.40,0.1287,4.291
2.166658,84.43,0.1308,4.359
2.249991,84.45,0.1328,4.425
2.333324,84.46,0.1348,4.494
2.416657,84.47,0.1370,4.566
2.499990,84.48,0.1390,4.635
2.583323,84.49,0.1411,4.704
2.666656,84.49,0.1432,4.773
2.749989,84.50,0.1452,4.839
2.833322,84.55,0.1473,4.910
2.916655,84.65,0.1493,4.978
2.999988,84.75,0.1515,5.049
3.083321,84.84,0.1536,5.119
3.166654,84.93,0.1556,5.188
3.249987,84.98,0.1577,5.255
3.333320,85.00,0.1597,5.323
3.416653,85.01,0.1618,5.392
3.499986,85.03,0.1639,5.463
3.583319,85.05,0.1660,5.533
3.666652,85.08,0.1680,5.602
3.749985,85.10,0.1701,5.669
3.833318,85.13,0.1721,5.735
3.916651,85.16,0.1741,5.803
3.999984,85.23,0.1763,5.877
4.083317,85.31,0.1784,5.947
4.166650,85.42,0.1805,6.015
4.249983,85.51,0.1825,6.084
4.333316,85.59,0.1846,6.153
4.416649,85.65,0.1866,6.219
4.499982,85.69,0.1887,6.291
4.583315,85.70,0.1908,6.360
4.666648,85.70,0.1930,6.432
4.749981,85.70,0.1950,6.499
4.833314,85.71,0.1970,6.566
4.916647,85.71,0.1990,6.633
4.999980,85.71,0.2011,6.703
5.083313,85.72,0.2032,6.773
5.166646,85.72,0.2054,6.845
5.249979,85.74,0.2074,6.914
5.333312,85.75,0.2094,6.981
5.416645,85.76,0.2114,7.046
5.499978,85.78,0.2135,7.118
5.583311,85.79,0.2156,7.187
5.666644,85.80,0.2177,7.258
5.749977,85.81,0.2198,7.328
5.833310,85.84,0.2219,7.396
5.916643,85.89,0.2239,7.463
5.999976,85.97,0.2260,7.532
6.083309,86.07,0.2281,7.602
6.166642,86.22,0.2301,7.671
6.249975,86.45,0.2322,7.740
6.333308,86.80,0.2343,7.810
6.416641,87.23,0.2363,7.877
6.499974,87.92,0.2384,7.945
6.583307,89.15,0.2405,8.016
6.666640,91.15,0.2426,8.087
6.749973,93.38,0.2448,8.160
6.833306,96.62,-0.006047,-0.2016
6.916639,100.6,-0.003971,-0.1324
6.999972,104.1,-0.003358,-0.1119
7.083305,106.9,-0.002951,-0.09836
7.166638,109.0,-0.002672,-0.08907
7.249971,110.3,-0.002522,-0.08407
7.333304,110.7,-0.002316,-0.07719
7.416637,110.8,-0.002194,-0.07312
7.499970,110.9,-0.002079,-0.06932
7.583303,111.0,-0.001965,-0.06551
7.666636,111.1,-0.001900,-0.06333
7.749969,111.1,-0.001837,-0.06123
7.833302,111.2,-0.001800,-0.06000
7.916635,111.2,-0.001709,-0.05696
7.999968,111.2,-0.001695,-0.05649
8.083301,111.2,-0.001600,-0.05333
8.166634,111.2,-0.001566,-0.05221
8.249967,111.2,-0.001500,-0.05000
8.333300,111.2,-0.001500,-0.05000
8.416633,111.2,-0.001424,-0.04746
8.499966,111.2,-0.001400,-0.04667
8.583299,111.2,-0.001400,-0.04667
8.666632,111.2,-0.001400,-0.04667
8.749965,111.2,-0.001367,-0.04557
8.833298,111.2,-0.001300,-0.04333
8.916631,111.1,-0.001300,-0.04333
8.999964,111.1,-0.001300,-0.04333
9.083297,111.1,-0.001300,-0.04333
9.166630,111.1,-0.001200,-0.04000
9.249963,111.1,-0.001200,-0.04000
9.333296,111.1,-0.001200,-0.04000
9.416629,111.1,-0.001200,-0.04000
9.499962,111.1,-0.001200,-0.04000
9.583295,111.0,-0.001200,-0.04000
9.666628,111.0,-0.001200,-0.04000
9.749961,111.0,-0.001100,-0.03667
9.833294,111.0,-0.001100,-0.03667
9.916627,111.0,-0.001100,-0.03667
9.999960,111.0,-0.001100,-0.03667
10.083293,110.9,-0.001100,-0.03667
10.166626,110.9,-0.001100,-0.03667
10.249959,110.9,-0.001100,-0.03667
10.333292,110.9,-0.001100,-0.03667
10.416625,110.9,-0.001084,-0.03614
10.499958,110.8,-0.001000,-0.03333
10.583291,110.8,-0.001000,-0.03333
10.666624,110.8,-0.0007081,-0.02360
10.749957,110.9,-0.0001373,-0.004576
10.833290,111.8,0.001542,0.05141
10.916623,113.6,0.003685,0.1228
10.999956,116.3,0.005838,0.1946
11.083289,119.8,0.007890,0.2630
11.166622,123.8,0.009942,0.3314
11.249955,127.8,0.01205,0.4016
11.333288,131.6,0.01415,0.4715
11.416621,135.3,0.01620,0.5399
11.499954,139.0,0.01835,0.6116
11.583287,142.6,0.02030,0.6768
11.666620,146.2,0.02238,0.7459
11.749953,149.8,0.02446,0.8154
11.833286,153.4,0.02658,0.8862
11.916619,157.1,0.02869,0.9564
11.999952,160.7,0.03076,1.025
12.083285,164.4,0.03281,1.094
12.166618,168.0,0.03486,1.162
12.249951,171.7,0.03692,1.231
12.333284,175.4,0.03901,1.300
12.416617,179.0,0.04112,1.371
12.499950,182.8,0.04324,1.441
12.583283,186.5,0.04525,1.508
12.666616,190.2,0.04728,1.576
12.749949,193.8,0.04940,1.647
12.833282,197.4,0.05148,1.716
12.916615,200.9,0.05353,1.784
12.999948,204.4,0.05563,1.854
13.083281,207.9,0.05769,1.923
13.166614,211.3,0.05969,1.990
13.249947,214.8,0.06174,2.058
13.333280,218.3,0.06389,2.130
13.416613,221.9,0.06594,2.198
13.499946,225.4,0.06800,2.267
13.583279,228.9,0.07005,2.335
13.666612,232.3,0.07210,2.403
13.749945,235.7,0.07416,2.472
13.833278,239.0,0.07629,2.543
13.916611,242.2,0.07836,2.612
13.999944,245.3,0.08050,2.683
14.083277,248.4,0.08250,2.750
14.166610,251.3,0.08451,2.817
14.249943,254.1,0.08656,2.885
14.333276,256.8,0.08869,2.956
14.416609,259.4,0.09077,3.026
14.499942,261.9,0.09284,3.095
14.583275,264.3,0.09496,3.165
14.666608,266.5,0.09695,3.232
14.749941,268.6,0.09900,3.300
14.833274,270.6,0.1011,3.370
14.916607,272.4,0.1032,3.439
14.999940,274.2,0.1052,3.508
15.083273,275.9,0.1074,3.579
15.166606,277.5,0.1093,3.645
15.249939,279.0,0.1114,3.713
15.333272,280.4,0.1135,3.783
15.416605,281.8,0.1156,3.853
15.499938,283.1,0.1176,3.921
15.583271,284.4,0.1197,3.990
15.666604,285.6,0.1217,4.058
15.749937,286.7,0.1238,4.126
15.833270,287.8,0.1259,4.196
15.916603,288.9,0.1280,4.267
15.999936,290.0,0.1301,4.337
16.083269,291.0,0.1322,4.407
16.166602,292.0,0.1342,4.474
16.249935,292.9,0.1362,4.540
16.333268,293.8,0.1384,4.612
16.416601,294.7,0.1405,4.683
16.499934,295.6,0.1426,4.752
16.583267,296.4,0.1446,4.821
16.666600,297.3,0.1467,4.889
16.749933,298.1,0.1487,4.956
16.833266,298.9,0.1507,5.023
16.916599,299.7,0.1529,5.096
16.999932,300.5,0.1549,5.165
17.083265,301.3,0.1570,5.234
17.166598,302.0,0.1591,5.303
17.249931,302.7,0.1611,5.371
17.333264,303.4,0.1632,5.440
17.416597,304.1,0.1653,5.508
17.499930,304.8,0.1674,5.580
17.583263,305.5,0.1694,5.648
17.666596,306.1,0.1715,5.716
17.749929,306.8,0.1735,5.785
17.833262,307.4,0.1756,5.853
17.916595,307.9,0.1776,5.921
17.999928,308.5,0.1798,5.993
18.083261,309.1,0.1819,6.062
18.166594,309.8,0.1839,6.131
18.249927,310.3,0.1860,6.199
18.333260,310.9,0.1880,6.265
18.416593,311.4,0.1900,6.334
18.499926,311.9,0.1922,6.406
18.583259,312.5,0.1943,6.478
18.666592,313.0,0.1963,6.544
18.749925,313.6,0.1985,6.615
18.833258,314.0,0.2004,6.680
18.916591,314.5,0.2024,6.748
18.999924,315.0,0.2046,6.819
19.083257,315.5,0.2067,6.890
19.166590,316.0,0.2088,6.960
19.249923,316.4,0.2109,7.029
19.333256,316.9,0.2128,7.094
19.416589,317.3,0.2149,7.163
19.499922,317.7,0.2170,7.233
19.583255,318.1,0.2191,7.303
19.666588,318.6,0.2212,7.374
19.749921,319.0,0.2233,7.443
19.833254,319.4,0.2253,7.510
19.916587,319.8,0.2273,7.577
19.999920,320.2,0.2294,7.646
20.083253,320.6,0.2315,7.718
20.166586,321.0,0.2336,7.788
20.249919,321.4,0.2357,7.857
20.333252,321.7,0.2377,7.923
20.416585,322.1,0.2397,7.990
20.499918,322.4,0.2419,8.062
20.583251,322.8,0.2439,8.131
20.666584,323.1,0.2460,8.201
20.749917,323.5,0.2481,8.271
20.833250,323.8,0.2502,8.339
20.916583,324.2,0.2521,8.405
20.999916,324.5,0.2543,8.475
21.083249,324.8,0.2563,8.544
21.166582,325.1,0.2584,8.613
21.249915,325.4,0.2605,8.685
21.333248,325.8,0.2626,8.753
21.416581,326.1,0.2646,8.820
21.499914,326.3,0.2667,8.889
21.583247,326.7,0.2687,8.958
21.666580,326.9,0.2708,9.027
21.749913,327.2,0.2729,9.098
21.833246,327.5,0.2750,9.166
21.916579,327.8,0.2770,9.235
21.999912,328.1,0.2791,9.302
22.083245,328.3,0.2811,9.371
22.166578,328.6,0.2832,9.440
22.249911,328.9,0.2853,9.511
22.333244,329.1,0.2874,9.580
22.416577,329.4,0.2894,9.645
22.499910,329.6,0.2914,9.714
22.583243,329.9,0.2935,9.784
22.666576,330.1,0.2956,9.854
22.749909,330.4,0.2977,9.925
22.833242,330.7,0.2998,9.994
22.916575,330.9,0.3019,10.06
22.999908,331.1,0.3039,10.13
23.083241,331.3,0.3060,10.20
23.166574,331.6,0.3081,10.27
23.249907,331.8,0.3102,10.34
23.333240,332.1,0.3122,10.41
23.416573,332.3,0.3143,10.48
23.499906,332.5,0.3163,10.54
23.583239,332.7,0.3184,10.61
23.666572,332.9,0.3205,10.68
23.749905,333.1,0.3225,10.75
23.833238,333.3,0.3246,10.82
23.916571,333.5,0.3267,10.89
23.999904,333.7,0.3287,10.96
24.083237,333.9,0.3307,11.02
24.166570,334.1,0.3329,11.10
24.249903,334.3,0.3350,11.17
24.333236,334.5,0.3370,11.23
24.416569,334.7,0.3391,11.30
24.499902,334.9,0.3412,11.37
24.583235,335.1,0.3432,11.44
24.666568,335.3,0.3454,11.51
24.749901,335.5,0.3474,11.58
24.833234,335.7,0.3496,11.65
24.916567,335.9,0.3516,11.72
24.999900,336.0,0.3537,11.79
25.083233,336.2,0.3557,11.86
25.166566,336.4,0.3578,11.93
25.249899,336.5,0.3599,12.00
25.333232,336.7,0.3620,12.07
25.416565,336.9,0.3640,12.13
25.499898,337.0,0.3661,12.20
25.583231,337.2,0.3681,12.27
25.666564,337.3,0.3702,12.34
25.749897,337.5,0.3723,12.41
25.833230,337.6,0.3744,12.48
25.916563,337.8,0.3764,12.55
25.999896,338.0,0.3785,12.62
26.083229,338.1,0.3805,12.68
26.166562,338.2,0.3826,12.75
26.249895,338.4,0.3847,12.82
26.333228,338.5,0.3868,12.89
26.416561,338.7,0.3888,12.96
26.499894,338.8,0.3909,13.03
26.583227,338.9,0.3929,13.10
26.666560,339.1,0.3950,13.17
26.749893,339.2,0.3972,13.24
26.833226,339.4,0.3992,13.31
26.916559,339.5,0.4013,13.38
26.999892,339.7,0.4033,13.44
27.083225,339.7,0.4054,13.51
27.166558,339.9,0.4074,13.58
27.249891,340.0,0.4096,13.65
27.333224,340.1,0.4117,13.72
27.416557,340.3,0.4137,13.79
27.499890,340.4,0.4158,13.86
27.583223,340.5,0.4178,13.93
27.666556,340.6,0.4198,13.99
27.749889,340.7,0.4220,14.07
27.833222,340.9,0.4240,14.13
27.916555,341.0,0.4261,14.20
27.999888,341.1,0.4282,14.27
28.083221,341.2,0.4302,14.34
28.166554,341.3,0.4322,14.41
28.249887,341.4,0.4343,14.48
28.333220,341.5,0.4364,14.55
28.416553,341.6,0.4385,14.62
28.499886,341.7,0.4406,14.69
28.583219,341.8,0.4426,14.75
28.666552,341.9,0.4446,14.82
28.749885,342.0,0.4467,14.89
28.833218,342.1,0.4489,14.96
28.916551,342.2,0.4509,15.03
28.999884,342.3,0.4530,15.10
29.083217,342.4,0.4550,15.17
29.166550,342.5,0.4570,15.23
29.249883,342.6,0.4591,15.30
29.333216,342.7,0.4613,15.38
29.416549,342.8,0.4634,15.45
29.499882,342.9,0.4654,15.51
29.583215,343.0,0.4675,15.58
29.666548,343.1,0.4695,15.65
29.749881,343.1,0.4715,15.72
29.833214,343.2,0.4737,15.79
29.916547,343.3,0.4758,15.86
29.999880,343.4,0.4779,15.93
30.083213,343.5,0.4799,16.00
30.166546,343.6,0.4819,16.06
30.249879,343.6,0.4840,16.13
30.333212,343.7,0.4861,16.20
30.416545,343.8,0.4882,16.27
30.499878,343.9,0.4903,16.34
30.583211,344.0,0.4923,16.41
30.666544,344.0,0.4943,16.48
30.749877,344.1,0.4964,16.55
30.833210,344.1,0.4985,16.62
30.916543,344.2,0.5006,16.69
30.999876,344.3,0.5027,16.76
31.083209,344.4,0.5048,16.83
31.166542,344.4,0.5067,16.89
31.249875,344.5,0.5088,16.96
31.333208,344.5,0.5109,17.03
31.416541,344.6,0.5130,17.10
31.499874,344.7,0.5151,17.17
31.583207,344.7,0.5172,17.24
31.666540,344.8,0.5192,17.31
31.749873,344.9,0.5213,17.38
31.833206,344.9,0.5233,17.44
31.916539,344.9,0.5254,17.51
31.999872,345.0,0.5275,17.58
32.083205,345.1,0.5296,17.65
32.166538,345.2,0.5317,17.72
32.249871,345.2,0.5337,17.79
32.333204,345.2,0.5357,17.86
32.416537,345.3,0.5378,17.93
32.499870,345.3,0.5399,18.00
32.583203,345.4,0.5420,18.07
32.666536,345.5,0.5441,18.14
32.749869,345.5,0.5461,18.20
32.833202,345.5,0.5481,18.27
32.916535,345.6,0.5503,18.34
32.999868,345.6,0.5524,18.41
33.083201,345.6,0.5544,18.48
33.166534,345.7,0.5565,18.55
33.249867,345.7,0.5585,18.62
33.333200,345.7,0.5606,18.69
33.416533,345.8,0.5627,18.76
33.499866,345.8,0.5648,18.83
33.583199,345.9,0.5668,18.89
33.666532,346.0,0.5689,18.96
33.749865,346.0,0.5710,19.03
33.833198,346.0,0.5730,19.10
33.916531,346.0,0.5751,19.17
33.999864,346.1,0.5772,19.24
34.083197,346.1,0.5792,19.31
34.166530,346.2,0.5813,19.38
34.249863,346.2,0.5834,19.45
34.333196,346.2,0.5854,19.51
34.416529,346.2,0.5875,19.58
34.499862,346.3,0.5896,19.65
34.583195,346.3,0.5916,19.72
34.666528,346.3,0.5938,19.79
34.749861,346.4,0.5958,19.86
34.833194,346.4,0.5978,19.93
34.916527,346.4,0.5999,20.00
34.999860,346.5,0.6020,20.07
35.083193,346.5,0.6041,20.14
35.166526,346.5,0.6062,20.21
35.249859,346.6,0.6082,20.27
35.333192,346.6,0.6102,20.34
35.416525,346.6,0.6124,20.41
35.499858,346.6,0.6144,20.48
35.583191,346.6,0.6165,20.55
35.666524,346.6,0.6186,20.62
35.749857,346.7,0.6206,20.69
35.833190,346.7,0.6226,20.75
35.916523,346.7,0.6247,20.82
35.999856,346.7,0.6268,20.89
36.083189,346.7,0.6289,20.96
36.166522,346.7,0.6309,21.03
36.249855,346.7,0.6330,21.10
36.333188,346.8,0.6350,21.17
36.416521,346.7,0.6371,21.24
36.499854,346.8,0.6392,21.31
36.583187,346.8,0.6413,21.38
36.666520,346.8,0.6434,21.45
36.749853,346.8,0.6455,21.52
36.833186,346.8,0.6475,21.58
36.916519,346.8,0.6495,21.65
36.999852,346.8,0.6516,21.72
37.083185,346.8,0.6537,21.79
37.166518,346.9,0.6558,21.86
37.249851,346.9,0.6579,21.93
37.333184,346.9,0.6599,22.00
37.416517,346.9,0.6619,22.06
37.499850,346.9,0.6640,22.13
37.583183,346.9,0.6661,22.20
37.666516,346.9,0.6682,22.27
37.749849,346.9,0.6703,22.34
37.833182,346.9,0.6723,22.41
37.916515,346.9,0.6743,22.48
37.999848,346.9,0.6764,22.55
38.083181,346.9,0.6785,22.62
38.166514,346.9,0.6806,22.69
38.249847,346.9,0.6826,22.75
38.333180,346.9,0.6846,22.82
38.416513,346.9,0.6866,22.89
38.499846,346.8,0.6887,22.96
38.583179,346.8,0.6908,23.03
38.666512,346.8,0.6930,23.10
38.749845,346.9,0.6950,23.17
38.833178,346.9,0.6971,23.24
38.916511,346.9,0.6990,23.30
38.999844,346.8,0.7012,23.37
39.083177,346.8,0.7033,23.44
39.166510,346.8,0.7054,23.51
39.249843,346.8,0.7074,23.58
39.333176,346.8,0.7095,23.65
39.416509,346.8,0.7115,23.72
39.499842,346.7,0.7136,23.79
39.583175,346.7,0.7157,23.86
39.666508,346.7,0.7178,23.93
39.749841,346.7,0.7199,24.00
39.833174,346.7,0.7220,24.07
39.916507,346.7,0.7240,24.13
39.999840,346.6,0.7260,24.20
40.083173,346.6,0.7281,24.27
40.166506,346.6,0.7303,24.34
40.249839,346.5,0.7323,24.41
40.333172,346.5,0.7344,24.48
40.416505,346.5,0.7364,24.55
40.499838,346.5,0.7385,24.62
40.583171,346.4,0.7405,24.68
40.666504,346.4,0.7427,24.76
40.749837,346.4,0.7447,24.82
40.833170,346.4,0.7468,24.89
40.916503,346.4,0.7489,24.96
40.999836,346.4,0.7509,25.03
41.083169,346.3,0.7529,25.10
41.166502,346.3,0.7551,25.17
41.249835,346.2,0.7572,25.24
41.333168,346.2,0.7593,25.31
41.416501,346.2,0.7613,25.38
41.499834,346.2,0.7634,25.45
41.583167,346.1,0.7654,25.51
41.666500,346.1,0.7675,25.58
41.749833,346.1,0.7696,25.65
41.833166,346.0,0.7717,25.72
41.916499,346.0,0.7738,25.79
41.999832,346.0,0.7758,25.86
42.083165,345.9,0.7778,25.93
42.166498,345.9,0.7799,26.00
42.249831,345.8,0.7820,26.07
42.333164,345.8,0.7841,26.14
42.416497,345.8,0.7862,26.21
42.499830,345.8,0.7883,26.28
42.583163,345.7,0.7902,26.34
42.666496,345.6,0.7923,26.41
42.749829,345.6,0.7944,26.48
42.833162,345.5,0.7965,26.55
42.916495,345.5,0.7986,26.62
42.999828,345.5,0.8007,26.69
43.083161,345.4,0.8026,26.75
43.166494,345.4,0.8047,26.82
43.249827,345.3,0.8068,26.89
43.333160,345.2,0.8089,26.96
43.416493,345.2,0.8110,27.03
43.499826,345.2,0.8131,27.10
43.583159,345.1,0.8151,27.17
43.666492,345.0,0.8171,27.24
43.749825,345.0,0.8192,27.31
43.833158,344.9,0.8213,27.38
43.916491,344.9,0.8234,27.45
43.999824,344.8,0.8255,27.52
44.083157,344.8,0.8275,27.58
44.166490,344.7,0.8295,27.65
44.249823,344.6,0.8317,27.72
44.333156,344.6,0.8337,27.79
44.416489,344.5,0.8358,27.86
44.499822,344.5,0.8379,27.93
44.583155,344.4,0.8400,28.00
44.666488,344.3,0.8420,28.07
44.749821,344.3,0.8441,28.14
44.833154,344.2,0.8461,28.20
44.916487,344.1,0.8483,28.28
44.999820,344.1,0.8503,28.34
45.083153,344.0,0.8524,28.41
45.166486,343.9,0.8544,28.48
45.249819,343.8,0.8565,28.55
45.333152,343.8,0.8585,28.62
45.416485,343.7,0.8607,28.69
45.499818,343.6,0.8627,28.76
45.583151,343.5,0.8648,28.83
45.666484,343.4,0.8668,28.89
45.749817,343.3,0.8688,28.96
45.833150,343.3,0.8709,29.03
45.916483,343.2,0.8730,29.10
45.999816,343.1,0.8751,29.17
46.083149,343.0,0.8772,29.24
46.166482,342.9,0.8792,29.31
46.249815,342.8,0.8813,29.38
46.333148,342.8,0.8834,29.45
46.416481,342.7,0.8855,29.52
46.499814,342.6,0.8876,29.59
46.583147,342.5,0.8897,29.66
46.666480,342.4,0.8917,29.72
46.749813,342.3,0.8937,29.79
46.833146,342.2,0.8958,29.86
46.916479,342.1,0.8979,29.93
46.999812,342.0,0.9000,30.00
47.083145,341.9,0.9020,30.07
47.166478,341.8,0.9041,30.14
47.249811,341.7,0.9061,30.20
47.333144,341.5,0.9082,30.27
47.416477,341.5,0.9103,30.34
47.499810,341.3,0.9124,30.41
47.583143,341.2,0.9145,30.48
47.666476,341.1,0.9165,30.55
47.749809,341.0,0.9185,30.62
47.833142,340.8,0.9206,30.69
47.916475,340.7,0.9228,30.76
47.999808,340.6,0.9248,30.83
48.083141,340.5,0.9269,30.90
48.166474,340.4,0.9289,30.96
48.249807,340.2,0.9310,31.03
48.333140,340.1,0.9330,31.10
48.416473,340.0,0.9352,31.17
48.499806,339.8,0.9372,31.24
48.583139,339.7,0.9393,31.31
48.666472,339.6,0.9414,31.38
48.749805,339.4,0.9434,31.45
48.833138,339.2,0.9454,31.51
48.916471,339.1,0.9476,31.59
48.999804,339.0,0.9497,31.66
49.083137,338.8,0.9518,31.73
49.166470,338.7,0.9538,31.79
49.249803,338.5,0.9559,31.86
49.333136,338.4,0.9579,31.93
49.416469,338.2,0.9600,32.00
49.499802,338.0,0.9621,32.07
49.583135,337.9,0.9642,32.14
49.666468,337.7,0.9663,32.21
49.749801,337.6,0.9683,32.28
49.833134,337.4,0.9703,32.34
49.916467,337.2,0.9724,32.41
49.999800,337.0,0.9745,32.48
50.083133,336.9,0.9766,32.55
50.166466,336.7,0.9787,32.62
50.249799,336.6,0.9807,32.69
50.333132,336.3,0.9827,32.76
50.416465,336.1,0.9847,32.82
50.499798,336.0,0.9869,32.90
50.583131,335.8,0.9890,32.97
50.666464,335.6,0.9911,33.04
50.749797,335.5,0.9931,33.10
50.833130,335.2,0.9951,33.17
50.916463,335.0,0.9971,33.24
50.999796,334.8,0.9993,33.31
51.083129,334.6,1.001,33.38
51.166462,334.4,1.003,33.45
51.249795,334.2,1.006,33.52
51.333128,334.0,1.008,33.59
51.416461,333.8,1.010,33.65
51.499794,333.5,1.012,33.72
51.583127,333.3,1.014,33.79
51.666460,333.1,1.016,33.86
51.749793,332.9,1.018,33.93
51.833126,332.7,1.020,34.00
51.916459,332.4,1.022,34.07
51.999792,332.2,1.024,34.14
52.083125,332.0,1.026,34.21
52.166458,331.7,1.028,34.28
52.249791,331.5,1.030,34.35
52.333124,331.3,1.032,34.41
52.416457,331.0,1.034,34.48
52.499790,330.7,1.037,34.55
52.583123,330.4,1.039,34.62
52.666456,330.2,1.041,34.69
52.749789,329.9,1.043,34.76
52.833122,329.7,1.045,34.83
52.916455,329.4,1.047,34.90
52.999788,329.2,1.049,34.96
53.083121,328.9,1.051,35.04
53.166454,328.6,1.053,35.10
53.249787,328.4,1.055,35.17
53.333120,328.1,1.057,35.24
53.416453,327.8,1.059,35.31
53.499786,327.5,1.061,35.38
53.583119,327.3,1.063,35.45
53.666452,327.0,1.066,35.52
53.749785,326.7,1.068,35.59
53.833118,326.5,1.070,35.66
53.916451,326.2,1.072,35.72
53.999784,325.8,1.074,35.79
54.083117,325.6,1.076,35.86
54.166450,325.2,1.078,35.93
54.249783,324.9,1.080,36.00
54.333116,324.7,1.082,36.07
54.416449,324.4,1.084,36.14
54.499782,324.0,1.086,36.21
54.583115,323.7,1.088,36.28
54.666448,323.4,1.090,36.35
54.749781,323.1,1.093,36.42
54.833114,322.8,1.095,36.49
54.916447,322.4,1.097,36.55
54.999780,322.1,1.099,36.62
55.083113,321.7,1.101,36.69
55.166446,321.4,1.103,36.76
55.249779,321.1,1.105,36.83
55.333112,320.7,1.107,36.90
55.416445,320.4,1.109,36.97
55.499778,320.0,1.111,37.04
55.583111,319.7,1.113,37.11
55.666444,319.3,1.115,37.18
55.749777,319.0,1.117,37.25
55.833110,318.6,1.119,37.32
55.916443,318.3,1.122,37.38
55.999776,317.9,1.124,37.45
56.083109,317.5,1.126,37.52
56.166442,317.1,1.128,37.59
56.249775,316.8,1.130,37.66
56.333108,316.4,1.132,37.73
56.416441,316.0,1.134,37.80
56.499774,315.6,1.136,37.87
56.583107,315.2,1.138,37.94
56.666440,314.8,1.140,38.01
56.749773,314.4,1.142,38.08
56.833106,314.0,1.144,38.14
56.916439,313.6,1.146,38.21
56.999772,313.2,1.148,38.28
57.083105,312.8,1.150,38.35
57.166438,312.4,1.153,38.42
57.249771,312.0,1.155,38.49
57.333104,311.6,1.157,38.56
57.416437,311.2,1.159,38.63
57.499770,310.8,1.161,38.69
57.583103,310.3,1.163,38.76
57.666436,309.9,1.165,38.83
57.749769,309.5,1.167,38.90
57.833102,309.0,1.169,38.97
57.916435,308.6,1.171,39.04
57.999768,308.2,1.173,39.11
58.083101,307.7,1.175,39.18
58.166434,307.2,1.177,39.25
58.249767,306.8,1.179,39.32
58.333100,306.3,1.182,39.39
58.416433,305.9,1.184,39.46
58.499766,305.4,1.186,39.52
58.583099,304.9,1.188,39.59
58.666432,304.5,1.190,39.66
58.749765,304.0,1.192,39.73
58.833098,303.5,1.194,39.80
58.916431,303.1,1.196,39.87
58.999764,302.6,1.198,39.94
59.083097,302.1,1.200,40.01
59.166430,301.6,1.202,40.08
59.249763,301.1,1.204,40.15
59.333096,300.6,1.206,40.22
59.416429,300.1,1.209,40.29
59.499762,299.6,1.211,40.35
59.583095,299.1,1.213,40.42
59.666428,298.5,1.215,40.49
59.749761,298.0,1.217,40.56
59.833094,297.5,1.219,40.63
59.916427,297.0,1.221,40.70
59.999760,296.5,1.223,40.77
60.083093,296.0,1.225,40.83
60.166426,295.4,1.227,40.90
60.249759,294.9,1.229,40.97
60.333092,294.3,1.231,41.04
60.416425,293.8,1.233,41.11
60.499758,293.3,1.235,41.18
60.583091,292.7,1.237,41.25
60.666424,292.1,1.239,41.32
60.749757,291.5,1.242,41.38
60.833090,291.0,1.244,41.46
60.916423,290.4,1.246,41.53
60.999756,289.9,1.248,41.59
61.083089,289.3,1.250,41.66
61.166422,288.7,1.252,41.73
61.249755,288.1,1.254,41.80
61.333088,287.5,1.256,41.87
61.416421,286.9,1.258,41.94
61.499754,286.2,1.260,42.01
61.583087,285.7,1.262,42.08
61.666420,285.1,1.264,42.14
61.749753,284.5,1.266,42.21
61.833086,283.9,1.268,42.28
61.916419,283.2,1.271,42.35
61.999752,282.6,1.273,42.42
62.083085,282.0,1.275,42.49
62.166418,281.4,1.277,42.55
62.249751,280.7,1.279,42.62
62.333084,280.1,1.281,42.69
62.416417,279.4,1.283,42.76
62.499750,278.8,1.285,42.83
62.583083,278.2,1.287,42.90
62.666416,277.5,1.289,42.97
62.749749,276.8,1.291,43.04
62.833082,276.2,1.293,43.11
62.916415,275.5,1.295,43.18
62.999748,274.8,1.297,43.25
63.083081,274.1,1.300,43.32
63.166414,273.4,1.302,43.39
63.249747,272.7,1.304,43.45
63.333080,272.0,1.306,43.52
63.416413,271.3,1.308,43.59
63.499746,270.6,1.310,43.66
63.583079,269.9,1.312,43.73
63.666412,269.2,1.314,43.80
63.749745,268.5,1.316,43.87
63.833078,267.7,1.318,43.94
63.916411,267.0,1.320,44.01
63.999744,266.3,1.322,44.08
64.083077,265.6,1.324,44.15
64.166410,264.8,1.326,44.21
64.249743,264.0,1.328,44.28
64.333076,263.3,1.330,44.35
64.416409,262.5,1.333,44.42
64.499742,261.7,1.335,44.49
64.583075,261.0,1.337,44.56
64.666408,260.2,1.339,44.63
64.749741,259.4,1.341,44.69
64.833074,258.6,1.343,44.76
64.916407,257.8,1.345,44.83
64.999740,257.0,1.347,44.91
65.083073,256.2,1.349,44.98
65.166406,255.4,1.351,45.05
65.249739,254.6,1.353,45.11
65.333072,253.8,1.355,45.18
65.416405,252.9,1.358,45.25
65.499738,252.1,1.360,45.32
65.583071,251.2,1.362,45.39
65.666404,250.4,1.364,45.46
65.749737,249.6,1.366,45.53
65.833070,248.7,1.368,45.59
65.916403,247.8,1.370,45.66
65.999736,247.0,1.372,45.73
66.083069,246.1,1.374,45.80
66.166402,245.2,1.376,45.87
66.249735,244.3,1.378,45.94
66.333068,243.4,1.380,46.01
66.416401,242.5,1.382,46.08
66.499734,241.6,1.384,46.15
66.583067,240.7,1.387,46.22
66.666400,239.8,1.389,46.29
66.749733,238.9,1.391,46.36
66.833066,237.9,1.393,46.42
66.916399,237.0,1.395,46.49
66.999732,236.1,1.397,46.56
67.083065,235.1,1.399,46.63
67.166398,234.2,1.401,46.70
67.249731,233.2,1.403,46.77
67.333064,232.2,1.405,46.84
67.416397,231.2,1.407,46.90
67.499730,230.3,1.409,46.98
67.583063,229.3,1.411,47.04
67.666396,228.2,1.413,47.11
67.749729,227.2,1.416,47.18
67.833062,226.2,1.417,47.25
67.916395,225.2,1.420,47.32
67.999728,224.1,1.422,47.39
68.083061,223.1,1.424,47.46
68.166394,222.1,1.426,47.53
68.249727,221.0,1.428,47.60
68.333060,219.9,1.430,47.66
68.416393,218.8,1.432,47.73
68.499726,217.8,1.434,47.80
68.583059,216.7,1.436,47.87
68.666392,215.6,1.438,47.94
68.749725,214.4,1.440,48.01
68.833058,213.3,1.442,48.08
68.916391,212.2,1.444,48.15
68.999724,211.0,1.447,48.22
69.083057,209.9,1.449,48.29
69.166390,208.7,1.451,48.36
69.249723,207.5,1.453,48.43
69.333056,206.3,1.455,48.49
69.416389,205.1,1.457,48.56
69.499722,203.9,1.459,48.63
69.583055,202.7,1.461,48.70
69.666388,201.4,1.463,48.77
69.749721,200.2,1.465,48.84
69.833054,198.9,1.467,48.91
69.916387,197.6,1.469,48.97
69.999720,196.4,1.471,49.04
70.083053,195.1,1.473,49.12
70.166386,193.8,1.476,49.18
70.249719,192.4,1.478,49.25
70.333052,191.1,1.480,49.32
70.416385,189.7,1.482,49.39
70.499718,188.3,1.484,49.46
70.583051,187.0,1.486,49.53
70.666384,185.5,1.488,49.60
70.749717,184.1,1.490,49.67
70.833050,182.7,1.492,49.74
70.916383,181.2,1.494,49.80
70.999716,179.7,1.496,49.87
71.083049,178.2,1.498,49.94
71.166382,176.8,1.500,50.01
71.249715,175.2,1.502,50.08
71.333048,173.7,1.505,50.15
71.416381,172.1,1.507,50.22
71.499714,170.4,1.509,50.29
71.583047,168.8,1.511,50.36
71.666380,167.1,1.513,50.43
71.749713,165.4,1.515,50.50
71.833046,163.7,1.517,50.57
71.916379,161.9,1.519,50.63
71.999712,160.1,1.521,50.70
72.083045,158.3,1.523,50.77
72.166378,156.4,1.525,50.84
72.249711,154.5,1.527,50.91
72.333044,152.5,1.529,50.98
72.416377,150.4,1.531,51.05
72.499710,148.1,1.533,51.11
72.583043,145.8,1.535,51.18
72.666376,143.1,1.538,51.25
72.749709,140.2,1.540,51.32
72.833042,137.0,1.542,51.39
72.916375,127.2,1.544,51.46
72.999708,99.21,1.546,51.53
73.083041,71.18,1.548,51.59